Workbook

Sheet LMC
A1: Prearmados | B1: Faltan Precios | C1: Falta Estructura | D1: Productos en 0 | E1: Estructuras Comunes
B2: =IFERROR(__xludf.DUMMYFUNCTION("sort(filter(Prearmados!$E:$E,Prearmados!$I:$I=B1),filter(Prearmados!$J:$J,Prearmados!$I:$I=B1),1)"),"#N/A") -> #N/A | C2: =IFERROR(__xludf.DUMMYFUNCTION("unique(filter(Prearmados!$E:$E,Prearmados!$I:$I=C1))"),"Tanque Combustible 3000 lts Plastico") -> Tanque Combustible 3000 lts Plastico | D2: =IFERROR(__xludf.DUMMYFUNCTION("unique(filter(Precio_Productos!B3:B17,Precio_Productos!E3:E17=0))"),"#N/A") -> #N/A | E2: =IFERROR(__xludf.DUMMYFUNCTION("unique(filter(Estructuras!F:F,Estructuras!C:C=Precio_Productos!A18))"),"Tanque Combinado 3000 lts C/Taller") -> Tanque Combinado 3000 lts C/Taller
C3: =IFERROR(__xludf.DUMMYFUNCTION("""COMPUTED_VALUE"""),"Tanque Combustible 3500 lts Plastico") -> Tanque Combustible 3500 lts Plastico | E3: =IFERROR(__xludf.DUMMYFUNCTION("""COMPUTED_VALUE"""),"Tanque Combinado 4000 lts C/Taller") -> Tanque Combinado 4000 lts C/Taller
C4: =IFERROR(__xludf.DUMMYFUNCTION("""COMPUTED_VALUE"""),"Tanque Combinado Plastico") -> Tanque Combinado Plastico
C5: =IFERROR(__xludf.DUMMYFUNCTION("""COMPUTED_VALUE"""),"Tanque 8000 lts") -> Tanque 8000 lts
C6: =IFERROR(__xludf.DUMMYFUNCTION("""COMPUTED_VALUE"""),"Elevador Frontal M1001 Reforzado") -> Elevador Frontal M1001 Reforzado
C7: =IFERROR(__xludf.DUMMYFUNCTION("""COMPUTED_VALUE"""),"Elevador Frontal C/Paralelogramo M1002 Reforzado") -> Elevador Frontal C/Paralelogramo M1002 Reforzado
C8: =IFERROR(__xludf.DUMMYFUNCTION("""COMPUTED_VALUE"""),"Desmalezadora de Arrastre 2,00") -> Desmalezadora de Arrastre 2,00

Sheet Validaciones Cotizador
A1: Implemento | B1: Ordenes | C1: Indice | D1: Cantidad | E1: Superpocisión | F1: Dejar Vacío | G1: Seleccionado | I1: Variable | J1: Dimension | L1: Implemento | M1: ID_Filtro | N1: Orden | O1: Indice | P1: Unidad | Q1: Código | R1: Cant | S1: Check_Comp | T1: Check_Prop | U1: Descripcion | V1: 1 | W1: Minimo | X1: Máximo | Y1: 2 | Z1: Minimo | AA1: Máximo | AB1: 3 | AC1: Minimo | AD1: Máximo
A2: {=IF(COUNTIF(A$1:A1,Cotizador!F$2)=maxifs(Familias!E:E,Familias!D:D,Cotizador!F$2),IF(COUNTIF(A$1:A1,XLOOKUP(Cotizador!F$2,Implementos!B:B,Implementos!C:C,"",0,1))=SUMIFS(Implementos!D:D,Implementos!B:B,Cotizador!F$2,Implementos!C:C,XLOOKUP(Cotizador!F$2,Implementos!B:B,Implementos!C:C,"",0,1)),"",XLOOKUP(Cotizador!F$2,Implementos!B:B,Implementos!C:C,"",0,1)),Cotizador!F$2)} -> Acoplados Rurales | B2: =IF(A2="","",COUNTIF(A$1:A2,A2)) -> 1 | C2: {=IF(B2="","",IF(A2=XLOOKUP(A$2,Implementos!B:B,Implementos!C:C,"",0,1),B2+maxifs(B$1:B1,A$1:A1,A$2),B2))} -> 1 | D2: =IF(B2="","", COUNTIFS(Productos!F:F,A2,Productos!H:H,B2)+IF(F2="SI",0,1)) -> 28 | E2: =IFERROR(__xludf.DUMMYFUNCTION("IF($B2="""","""",INDEX(filter(Familias!F:F,Familias!$D:$D=$A2,Familias!$E:$E=$B2),1))"),"Y") -> Y | F2: =IFERROR(__xludf.DUMMYFUNCTION("IF($B2="""","""",INDEX(filter(Familias!G:G,Familias!$D:$D=$A2,Familias!$E:$E=$B2),1))"),"NO") -> NO | G2: {=IF(C2=1,XLOOKUP(C2,Cotizador!D:D,Cotizador!E:E,"",0,1),"")} -> 56 | I2: =IFERROR(__xludf.DUMMYFUNCTION("TRANSPOSE(filter(Cotizador!I1:V1,Cotizador!I2:V2>0))"),"Capacidad") -> Capacidad | J2: =IF(I2="","",SUMIF(Cotizador!I$1:V$1,I2,Cotizador!I$2:V$2)) -> 5575 | L2: {=IF(COUNTIF(L$1:L1,A$2)=SUMIF(A:A,A$2,D:D),IF(COUNTIF(L$1:L1,XLOOKUP(A$2,Implementos!B:B,Implementos!C:C,"",0,1))=SUMIF(A:A,XLOOKUP(A$2,Implementos!B:B,Implementos!C:C,"",0,1),D:D),"",XLOOKUP(A$2,Implementos!B:B,Implementos!C:C,"",0,1)),A$2)} -> Acoplados Rurales | M2: =IF(L2="","",max(M$1:M1)+1) -> 1 | N2: =IF(L2="","",IF(N1="Orden",1,IF(COUNTIFS(N$1:N1,N1,L$1:L1,L2)=SUMIFS(D:D,B:B,N1,A:A,L2),IF(N1=maxifs(B:B,A:A,L2),"",maxifs(N$1:N1,L$1:L1,L2)+1),N1))) -> 1 | O2: =IF(N2="","",SUMIFS(C:C,B:B,N2,A:A,L2)) -> 1 | P2: =IF(N2="","",COUNTIFS(N$1:N2,N2,L$1:L2,L2)) -> 1 | Q2: =IF(U2="","",SUMIF(Productos!E:E,U2,Productos!A:A)) -> 45 | R2: {=IF(L2="","", max(1,SUMIF(I:I,XLOOKUP(U2,Productos!E:E,Productos!G:G,"",0,1),J:J)))} -> 1 | S2: =IF(Q2="","",IF(SUMIFS(Compat_Vetado!D:D,Compat_Vetado!B:B,SUM(G:G),Compat_Vetado!C:C,Q2)=1,"SI",IF(OR(SUMIF(Cotizador!E:E,Q2,Cotizador!G:G)>0,SUMIFS(Compat_Vetado!D:D,Compat_Vetado!B:B,SUM(G:G),Compat_Vetado!C:C,Q2)=-1),"NO",""))) | T2: =IF(Q2="","",IF(S2="SI","x",IF(S2="NO","",IF(AND(OR(V2="",AND(W2<=SUMIF(I:I,V2,J:J),SUMIF(I:I,V2,J:J)<=X2)),OR(Y2="",AND(Z2<=SUMIF(I:I,Y2,J:J),SUMIF(I:I,Y2,J:J)<=AA2)),OR(AB2="",AND(AC2<=SUMIF(I:I,AB2,J:J),SUMIF(I:I,AB2,J:J)<=AD2))),"x","")))) -> x | U2: =IFERROR(__xludf.DUMMYFUNCTION("IF(P2="""","""",IFERROR(INDEX(filter(Productos!E:E,Productos!F:F=L2,Productos!H:H=N2),P2),IF(M2=SUM(D:D),""Finalizar"",""-"")))"),"Tanque Combustible 1100 lts Bajo") -> Tanque Combustible 1100 lts Bajo | V2: =IFERROR(__xludf.DUMMYFUNCTION("IF(OR($U2="""",COUNTIF($I:$I,IFERROR(unique(filter(Prod_Prop!$H:$H,Prod_Prop!$G:$G=$U2,Prod_Prop!$E:$E=V$1)),""Check""))=0),"""",IFERROR(unique(filter(Prod_Prop!$H:$H,Prod_Prop!$G:$G=$U2,Prod_Prop!$E:$E=V$1)),""""))"),"") | W2: =IF(V2="","",SUMIFS(Prod_Prop!$J:$J,Prod_Prop!$B:$B,$Q2,Prod_Prop!$H:$H,V2,Prod_Prop!$I:$I,W$1)*IF(V2="Peso",$R2,1)) | X2: =IF(V2="","",SUMIFS(Prod_Prop!$J:$J,Prod_Prop!$B:$B,$Q2,Prod_Prop!$H:$H,V2,Prod_Prop!$I:$I,X$1)*IF(V2="Peso",$R2,1)) | Y2: =IFERROR(__xludf.DUMMYFUNCTION("IF(OR($U2="""",COUNTIF($I:$I,IFERROR(unique(filter(Prod_Prop!$H:$H,Prod_Prop!$G:$G=$U2,Prod_Prop!$E:$E=Y$1)),""Check""))=0),"""",IFERROR(unique(filter(Prod_Prop!$H:$H,Prod_Prop!$G:$G=$U2,Prod_Prop!$E:$E=Y$1)),""""))"),"") | Z2: =IF(Y2="","",SUMIFS(Prod_Prop!$J:$J,Prod_Prop!$B:$B,$Q2,Prod_Prop!$H:$H,Y2,Prod_Prop!$I:$I,Z$1)*IF(Y2="Peso",$R2,1)) | AA2: =IF(Y2="","",SUMIFS(Prod_Prop!$J:$J,Prod_Prop!$B:$B,$Q2,Prod_Prop!$H:$H,Y2,Prod_Prop!$I:$I,AA$1)*IF(Y2="Peso",$R2,1)) | AB2: =IFERROR(__xludf.DUMMYFUNCTION("IF(OR($U2="""",COUNTIF($I:$I,IFERROR(unique(filter(Prod_Prop!$H:$H,Prod_Prop!$G:$G=$U2,Prod_Prop!$E:$E=AB$1)),""Check""))=0),"""",IFERROR(unique(filter(Prod_Prop!$H:$H,Prod_Prop!$G:$G=$U2,Prod_Prop!$E:$E=AB$1)),""""))"),"") | AC2: =IF(AB2="","",SUMIFS(Prod_Prop!$J:$J,Prod_Prop!$B:$B,$Q2,Prod_Prop!$H:$H,AB2,Prod_Prop!$I:$I,AC$1)*IF(AB2="Peso",$R2,1)) | AD2: =IF(AB2="","",SUMIFS(Prod_Prop!$J:$J,Prod_Prop!$B:$B,$Q2,Prod_Prop!$H:$H,AB2,Prod_Prop!$I:$I,AD$1)*IF(AB2="Peso",$R2,1))
A3: {=IF(COUNTIF(A$1:A2,Cotizador!F$2)=maxifs(Familias!E:E,Familias!D:D,Cotizador!F$2),IF(COUNTIF(A$1:A2,XLOOKUP(Cotizador!F$2,Implementos!B:B,Implementos!C:C,"",0,1))=SUMIFS(Implementos!D:D,Implementos!B:B,Cotizador!F$2,Implementos!C:C,XLOOKUP(Cotizador!F$2,Implementos!B:B,Implementos!C:C,"",0,1)),"",XLOOKUP(Cotizador!F$2,Implementos!B:B,Implementos!C:C,"",0,1)),Cotizador!F$2)} -> Acoplados Rurales | B3: =IF(A3="","",COUNTIF(A$1:A3,A3)) -> 2 | C3: {=IF(B3="","",IF(A3=XLOOKUP(A$2,Implementos!B:B,Implementos!C:C,"",0,1),B3+maxifs(B$1:B2,A$1:A2,A$2),B3))} -> 2 | D3: =IF(B3="","", COUNTIFS(Productos!F:F,A3,Productos!H:H,B3)+IF(F3="SI",0,1)) -> 11 | E3: =IFERROR(__xludf.DUMMYFUNCTION("IF($B3="""","""",INDEX(filter(Familias!F:F,Familias!$D:$D=$A3,Familias!$E:$E=$B3),1))"),"Y") -> Y | F3: =IFERROR(__xludf.DUMMYFUNCTION("IF($B3="""","""",INDEX(filter(Familias!G:G,Familias!$D:$D=$A3,Familias!$E:$E=$B3),1))"),"NO") -> NO | G3: {=IF(C3=1,XLOOKUP(C3,Cotizador!D:D,Cotizador!E:E,"",0,1),"")} | I3: =IFERROR(__xludf.DUMMYFUNCTION("""COMPUTED_VALUE"""),"Peso") -> Peso | J3: =IF(I3="","",SUMIF(Cotizador!I$1:V$1,I3,Cotizador!I$2:V$2)) -> 4841.25 | L3: {=IF(COUNTIF(L$1:L2,A$2)=SUMIF(A:A,A$2,D:D),IF(COUNTIF(L$1:L2,XLOOKUP(A$2,Implementos!B:B,Implementos!C:C,"",0,1))=SUMIF(A:A,XLOOKUP(A$2,Implementos!B:B,Implementos!C:C,"",0,1),D:D),"",XLOOKUP(A$2,Implementos!B:B,Implementos!C:C,"",0,1)),A$2)} -> Acoplados Rurales | M3: =IF(L3="","",max(M$1:M2)+1) -> 2 | N3: =IF(L3="","",IF(N2="Orden",1,IF(COUNTIFS(N$1:N2,N2,L$1:L2,L3)=SUMIFS(D:D,B:B,N2,A:A,L3),IF(N2=maxifs(B:B,A:A,L3),"",maxifs(N$1:N2,L$1:L2,L3)+1),N2))) -> 1 | O3: =IF(N3="","",SUMIFS(C:C,B:B,N3,A:A,L3)) -> 1 | P3: =IF(N3="","",COUNTIFS(N$1:N3,N3,L$1:L3,L3)) -> 2 | Q3: =IF(U3="","",SUMIF(Productos!E:E,U3,Productos!A:A)) -> 46 | R3: {=IF(L3="","", max(1,SUMIF(I:I,XLOOKUP(U3,Productos!E:E,Productos!G:G,"",0,1),J:J)))} -> 1 | S3: =IF(Q3="","",IF(SUMIFS(Compat_Vetado!D:D,Compat_Vetado!B:B,SUM(G:G),Compat_Vetado!C:C,Q3)=1,"SI",IF(OR(SUMIF(Cotizador!E:E,Q3,Cotizador!G:G)>0,SUMIFS(Compat_Vetado!D:D,Compat_Vetado!B:B,SUM(G:G),Compat_Vetado!C:C,Q3)=-1),"NO",""))) | T3: =IF(Q3="","",IF(S3="SI","x",IF(S3="NO","",IF(AND(OR(V3="",AND(W3<=SUMIF(I:I,V3,J:J),SUMIF(I:I,V3,J:J)<=X3)),OR(Y3="",AND(Z3<=SUMIF(I:I,Y3,J:J),SUMIF(I:I,Y3,J:J)<=AA3)),OR(AB3="",AND(AC3<=SUMIF(I:I,AB3,J:J),SUMIF(I:I,AB3,J:J)<=AD3))),"x","")))) -> x | U3: =IFERROR(__xludf.DUMMYFUNCTION("IF(P3="""","""",IFERROR(INDEX(filter(Productos!E:E,Productos!F:F=L3,Productos!H:H=N3),P3),IF(M3=SUM(D:D),""Finalizar"",""-"")))"),"Tanque Combustible 1500 lts Standard") -> Tanque Combustible 1500 lts Standard | V3: =IFERROR(__xludf.DUMMYFUNCTION("IF(OR($U3="""",COUNTIF($I:$I,IFERROR(unique(filter(Prod_Prop!$H:$H,Prod_Prop!$G:$G=$U3,Prod_Prop!$E:$E=V$1)),""Check""))=0),"""",IFERROR(unique(filter(Prod_Prop!$H:$H,Prod_Prop!$G:$G=$U3,Prod_Prop!$E:$E=V$1)),""""))"),"") | W3: =IF(V3="","",SUMIFS(Prod_Prop!$J:$J,Prod_Prop!$B:$B,$Q3,Prod_Prop!$H:$H,V3,Prod_Prop!$I:$I,W$1)*IF(V3="Peso",$R3,1)) | X3: =IF(V3="","",SUMIFS(Prod_Prop!$J:$J,Prod_Prop!$B:$B,$Q3,Prod_Prop!$H:$H,V3,Prod_Prop!$I:$I,X$1)*IF(V3="Peso",$R3,1)) | Y3: =IFERROR(__xludf.DUMMYFUNCTION("IF(OR($U3="""",COUNTIF($I:$I,IFERROR(unique(filter(Prod_Prop!$H:$H,Prod_Prop!$G:$G=$U3,Prod_Prop!$E:$E=Y$1)),""Check""))=0),"""",IFERROR(unique(filter(Prod_Prop!$H:$H,Prod_Prop!$G:$G=$U3,Prod_Prop!$E:$E=Y$1)),""""))"),"") | Z3: =IF(Y3="","",SUMIFS(Prod_Prop!$J:$J,Prod_Prop!$B:$B,$Q3,Prod_Prop!$H:$H,Y3,Prod_Prop!$I:$I,Z$1)*IF(Y3="Peso",$R3,1)) | AA3: =IF(Y3="","",SUMIFS(Prod_Prop!$J:$J,Prod_Prop!$B:$B,$Q3,Prod_Prop!$H:$H,Y3,Prod_Prop!$I:$I,AA$1)*IF(Y3="Peso",$R3,1)) | AB3: =IFERROR(__xludf.DUMMYFUNCTION("IF(OR($U3="""",COUNTIF($I:$I,IFERROR(unique(filter(Prod_Prop!$H:$H,Prod_Prop!$G:$G=$U3,Prod_Prop!$E:$E=AB$1)),""Check""))=0),"""",IFERROR(unique(filter(Prod_Prop!$H:$H,Prod_Prop!$G:$G=$U3,Prod_Prop!$E:$E=AB$1)),""""))"),"") | AC3: =IF(AB3="","",SUMIFS(Prod_Prop!$J:$J,Prod_Prop!$B:$B,$Q3,Prod_Prop!$H:$H,AB3,Prod_Prop!$I:$I,AC$1)*IF(AB3="Peso",$R3,1)) | AD3: =IF(AB3="","",SUMIFS(Prod_Prop!$J:$J,Prod_Prop!$B:$B,$Q3,Prod_Prop!$H:$H,AB3,Prod_Prop!$I:$I,AD$1)*IF(AB3="Peso",$R3,1))
A4: {=IF(COUNTIF(A$1:A3,Cotizador!F$2)=maxifs(Familias!E:E,Familias!D:D,Cotizador!F$2),IF(COUNTIF(A$1:A3,XLOOKUP(Cotizador!F$2,Implementos!B:B,Implementos!C:C,"",0,1))=SUMIFS(Implementos!D:D,Implementos!B:B,Cotizador!F$2,Implementos!C:C,XLOOKUP(Cotizador!F$2,Implementos!B:B,Implementos!C:C,"",0,1)),"",XLOOKUP(Cotizador!F$2,Implementos!B:B,Implementos!C:C,"",0,1)),Cotizador!F$2)} -> Acoplados Rurales | B4: =IF(A4="","",COUNTIF(A$1:A4,A4)) -> 3 | C4: {=IF(B4="","",IF(A4=XLOOKUP(A$2,Implementos!B:B,Implementos!C:C,"",0,1),B4+maxifs(B$1:B3,A$1:A3,A$2),B4))} -> 3 | D4: =IF(B4="","", COUNTIFS(Productos!F:F,A4,Productos!H:H,B4)+IF(F4="SI",0,1)) -> 21 | E4: =IFERROR(__xludf.DUMMYFUNCTION("IF($B4="""","""",INDEX(filter(Familias!F:F,Familias!$D:$D=$A4,Familias!$E:$E=$B4),1))"),"O") -> O | F4: =IFERROR(__xludf.DUMMYFUNCTION("IF($B4="""","""",INDEX(filter(Familias!G:G,Familias!$D:$D=$A4,Familias!$E:$E=$B4),1))"),"SI") -> SI | G4: {=IF(C4=1,XLOOKUP(C4,Cotizador!D:D,Cotizador!E:E,"",0,1),"")} | I4: =IFERROR(__xludf.DUMMYFUNCTION("""COMPUTED_VALUE"""),"Longitud") -> Longitud | J4: =IF(I4="","",SUMIF(Cotizador!I$1:V$1,I4,Cotizador!I$2:V$2)) -> 4.95 | L4: {=IF(COUNTIF(L$1:L3,A$2)=SUMIF(A:A,A$2,D:D),IF(COUNTIF(L$1:L3,XLOOKUP(A$2,Implementos!B:B,Implementos!C:C,"",0,1))=SUMIF(A:A,XLOOKUP(A$2,Implementos!B:B,Implementos!C:C,"",0,1),D:D),"",XLOOKUP(A$2,Implementos!B:B,Implementos!C:C,"",0,1)),A$2)} -> Acoplados Rurales | M4: =IF(L4="","",max(M$1:M3)+1) -> 3 | N4: =IF(L4="","",IF(N3="Orden",1,IF(COUNTIFS(N$1:N3,N3,L$1:L3,L4)=SUMIFS(D:D,B:B,N3,A:A,L4),IF(N3=maxifs(B:B,A:A,L4),"",maxifs(N$1:N3,L$1:L3,L4)+1),N3))) -> 1 | O4: =IF(N4="","",SUMIFS(C:C,B:B,N4,A:A,L4)) -> 1 | P4: =IF(N4="","",COUNTIFS(N$1:N4,N4,L$1:L4,L4)) -> 3 | Q4: =IF(U4="","",SUMIF(Productos!E:E,U4,Productos!A:A)) -> 47 | R4: {=IF(L4="","", max(1,SUMIF(I:I,XLOOKUP(U4,Productos!E:E,Productos!G:G,"",0,1),J:J)))} -> 1 | S4: =IF(Q4="","",IF(SUMIFS(Compat_Vetado!D:D,Compat_Vetado!B:B,SUM(G:G),Compat_Vetado!C:C,Q4)=1,"SI",IF(OR(SUMIF(Cotizador!E:E,Q4,Cotizador!G:G)>0,SUMIFS(Compat_Vetado!D:D,Compat_Vetado!B:B,SUM(G:G),Compat_Vetado!C:C,Q4)=-1),"NO",""))) | T4: =IF(Q4="","",IF(S4="SI","x",IF(S4="NO","",IF(AND(OR(V4="",AND(W4<=SUMIF(I:I,V4,J:J),SUMIF(I:I,V4,J:J)<=X4)),OR(Y4="",AND(Z4<=SUMIF(I:I,Y4,J:J),SUMIF(I:I,Y4,J:J)<=AA4)),OR(AB4="",AND(AC4<=SUMIF(I:I,AB4,J:J),SUMIF(I:I,AB4,J:J)<=AD4))),"x","")))) -> x | U4: =IFERROR(__xludf.DUMMYFUNCTION("IF(P4="""","""",IFERROR(INDEX(filter(Productos!E:E,Productos!F:F=L4,Productos!H:H=N4),P4),IF(M4=SUM(D:D),""Finalizar"",""-"")))"),"Tanque Combustible 1800 lts Standard") -> Tanque Combustible 1800 lts Standard | V4: =IFERROR(__xludf.DUMMYFUNCTION("IF(OR($U4="""",COUNTIF($I:$I,IFERROR(unique(filter(Prod_Prop!$H:$H,Prod_Prop!$G:$G=$U4,Prod_Prop!$E:$E=V$1)),""Check""))=0),"""",IFERROR(unique(filter(Prod_Prop!$H:$H,Prod_Prop!$G:$G=$U4,Prod_Prop!$E:$E=V$1)),""""))"),"") | W4: =IF(V4="","",SUMIFS(Prod_Prop!$J:$J,Prod_Prop!$B:$B,$Q4,Prod_Prop!$H:$H,V4,Prod_Prop!$I:$I,W$1)*IF(V4="Peso",$R4,1)) | X4: =IF(V4="","",SUMIFS(Prod_Prop!$J:$J,Prod_Prop!$B:$B,$Q4,Prod_Prop!$H:$H,V4,Prod_Prop!$I:$I,X$1)*IF(V4="Peso",$R4,1)) | Y4: =IFERROR(__xludf.DUMMYFUNCTION("IF(OR($U4="""",COUNTIF($I:$I,IFERROR(unique(filter(Prod_Prop!$H:$H,Prod_Prop!$G:$G=$U4,Prod_Prop!$E:$E=Y$1)),""Check""))=0),"""",IFERROR(unique(filter(Prod_Prop!$H:$H,Prod_Prop!$G:$G=$U4,Prod_Prop!$E:$E=Y$1)),""""))"),"") | Z4: =IF(Y4="","",SUMIFS(Prod_Prop!$J:$J,Prod_Prop!$B:$B,$Q4,Prod_Prop!$H:$H,Y4,Prod_Prop!$I:$I,Z$1)*IF(Y4="Peso",$R4,1)) | AA4: =IF(Y4="","",SUMIFS(Prod_Prop!$J:$J,Prod_Prop!$B:$B,$Q4,Prod_Prop!$H:$H,Y4,Prod_Prop!$I:$I,AA$1)*IF(Y4="Peso",$R4,1)) | AB4: =IFERROR(__xludf.DUMMYFUNCTION("IF(OR($U4="""",COUNTIF($I:$I,IFERROR(unique(filter(Prod_Prop!$H:$H,Prod_Prop!$G:$G=$U4,Prod_Prop!$E:$E=AB$1)),""Check""))=0),"""",IFERROR(unique(filter(Prod_Prop!$H:$H,Prod_Prop!$G:$G=$U4,Prod_Prop!$E:$E=AB$1)),""""))"),"") | AC4: =IF(AB4="","",SUMIFS(Prod_Prop!$J:$J,Prod_Prop!$B:$B,$Q4,Prod_Prop!$H:$H,AB4,Prod_Prop!$I:$I,AC$1)*IF(AB4="Peso",$R4,1)) | AD4: =IF(AB4="","",SUMIFS(Prod_Prop!$J:$J,Prod_Prop!$B:$B,$Q4,Prod_Prop!$H:$H,AB4,Prod_Prop!$I:$I,AD$1)*IF(AB4="Peso",$R4,1))
A5: {=IF(COUNTIF(A$1:A4,Cotizador!F$2)=maxifs(Familias!E:E,Familias!D:D,Cotizador!F$2),IF(COUNTIF(A$1:A4,XLOOKUP(Cotizador!F$2,Implementos!B:B,Implementos!C:C,"",0,1))=SUMIFS(Implementos!D:D,Implementos!B:B,Cotizador!F$2,Implementos!C:C,XLOOKUP(Cotizador!F$2,Implementos!B:B,Implementos!C:C,"",0,1)),"",XLOOKUP(Cotizador!F$2,Implementos!B:B,Implementos!C:C,"",0,1)),Cotizador!F$2)} -> Acoplados Rurales | B5: =IF(A5="","",COUNTIF(A$1:A5,A5)) -> 4 | C5: {=IF(B5="","",IF(A5=XLOOKUP(A$2,Implementos!B:B,Implementos!C:C,"",0,1),B5+maxifs(B$1:B4,A$1:A4,A$2),B5))} -> 4 | D5: =IF(B5="","", COUNTIFS(Productos!F:F,A5,Productos!H:H,B5)+IF(F5="SI",0,1)) -> 7 | E5: =IFERROR(__xludf.DUMMYFUNCTION("IF($B5="""","""",INDEX(filter(Familias!F:F,Familias!$D:$D=$A5,Familias!$E:$E=$B5),1))"),"Y") -> Y | F5: =IFERROR(__xludf.DUMMYFUNCTION("IF($B5="""","""",INDEX(filter(Familias!G:G,Familias!$D:$D=$A5,Familias!$E:$E=$B5),1))"),"NO") -> NO | G5: {=IF(C5=1,XLOOKUP(C5,Cotizador!D:D,Cotizador!E:E,"",0,1),"")} | I5: =IFERROR(__xludf.DUMMYFUNCTION("""COMPUTED_VALUE"""),"Altura") -> Altura | J5: =IF(I5="","",SUMIF(Cotizador!I$1:V$1,I5,Cotizador!I$2:V$2)) -> 870 | L5: {=IF(COUNTIF(L$1:L4,A$2)=SUMIF(A:A,A$2,D:D),IF(COUNTIF(L$1:L4,XLOOKUP(A$2,Implementos!B:B,Implementos!C:C,"",0,1))=SUMIF(A:A,XLOOKUP(A$2,Implementos!B:B,Implementos!C:C,"",0,1),D:D),"",XLOOKUP(A$2,Implementos!B:B,Implementos!C:C,"",0,1)),A$2)} -> Acoplados Rurales | M5: =IF(L5="","",max(M$1:M4)+1) -> 4 | N5: =IF(L5="","",IF(N4="Orden",1,IF(COUNTIFS(N$1:N4,N4,L$1:L4,L5)=SUMIFS(D:D,B:B,N4,A:A,L5),IF(N4=maxifs(B:B,A:A,L5),"",maxifs(N$1:N4,L$1:L4,L5)+1),N4))) -> 1 | O5: =IF(N5="","",SUMIFS(C:C,B:B,N5,A:A,L5)) -> 1 | P5: =IF(N5="","",COUNTIFS(N$1:N5,N5,L$1:L5,L5)) -> 4 | Q5: =IF(U5="","",SUMIF(Productos!E:E,U5,Productos!A:A)) -> 48 | R5: {=IF(L5="","", max(1,SUMIF(I:I,XLOOKUP(U5,Productos!E:E,Productos!G:G,"",0,1),J:J)))} -> 1 | S5: =IF(Q5="","",IF(SUMIFS(Compat_Vetado!D:D,Compat_Vetado!B:B,SUM(G:G),Compat_Vetado!C:C,Q5)=1,"SI",IF(OR(SUMIF(Cotizador!E:E,Q5,Cotizador!G:G)>0,SUMIFS(Compat_Vetado!D:D,Compat_Vetado!B:B,SUM(G:G),Compat_Vetado!C:C,Q5)=-1),"NO",""))) | T5: =IF(Q5="","",IF(S5="SI","x",IF(S5="NO","",IF(AND(OR(V5="",AND(W5<=SUMIF(I:I,V5,J:J),SUMIF(I:I,V5,J:J)<=X5)),OR(Y5="",AND(Z5<=SUMIF(I:I,Y5,J:J),SUMIF(I:I,Y5,J:J)<=AA5)),OR(AB5="",AND(AC5<=SUMIF(I:I,AB5,J:J),SUMIF(I:I,AB5,J:J)<=AD5))),"x","")))) -> x | U5: =IFERROR(__xludf.DUMMYFUNCTION("IF(P5="""","""",IFERROR(INDEX(filter(Productos!E:E,Productos!F:F=L5,Productos!H:H=N5),P5),IF(M5=SUM(D:D),""Finalizar"",""-"")))"),"Tanque Combustible 2000 lts Bajo") -> Tanque Combustible 2000 lts Bajo | V5: =IFERROR(__xludf.DUMMYFUNCTION("IF(OR($U5="""",COUNTIF($I:$I,IFERROR(unique(filter(Prod_Prop!$H:$H,Prod_Prop!$G:$G=$U5,Prod_Prop!$E:$E=V$1)),""Check""))=0),"""",IFERROR(unique(filter(Prod_Prop!$H:$H,Prod_Prop!$G:$G=$U5,Prod_Prop!$E:$E=V$1)),""""))"),"") | W5: =IF(V5="","",SUMIFS(Prod_Prop!$J:$J,Prod_Prop!$B:$B,$Q5,Prod_Prop!$H:$H,V5,Prod_Prop!$I:$I,W$1)*IF(V5="Peso",$R5,1)) | X5: =IF(V5="","",SUMIFS(Prod_Prop!$J:$J,Prod_Prop!$B:$B,$Q5,Prod_Prop!$H:$H,V5,Prod_Prop!$I:$I,X$1)*IF(V5="Peso",$R5,1)) | Y5: =IFERROR(__xludf.DUMMYFUNCTION("IF(OR($U5="""",COUNTIF($I:$I,IFERROR(unique(filter(Prod_Prop!$H:$H,Prod_Prop!$G:$G=$U5,Prod_Prop!$E:$E=Y$1)),""Check""))=0),"""",IFERROR(unique(filter(Prod_Prop!$H:$H,Prod_Prop!$G:$G=$U5,Prod_Prop!$E:$E=Y$1)),""""))"),"") | Z5: =IF(Y5="","",SUMIFS(Prod_Prop!$J:$J,Prod_Prop!$B:$B,$Q5,Prod_Prop!$H:$H,Y5,Prod_Prop!$I:$I,Z$1)*IF(Y5="Peso",$R5,1)) | AA5: =IF(Y5="","",SUMIFS(Prod_Prop!$J:$J,Prod_Prop!$B:$B,$Q5,Prod_Prop!$H:$H,Y5,Prod_Prop!$I:$I,AA$1)*IF(Y5="Peso",$R5,1)) | AB5: =IFERROR(__xludf.DUMMYFUNCTION("IF(OR($U5="""",COUNTIF($I:$I,IFERROR(unique(filter(Prod_Prop!$H:$H,Prod_Prop!$G:$G=$U5,Prod_Prop!$E:$E=AB$1)),""Check""))=0),"""",IFERROR(unique(filter(Prod_Prop!$H:$H,Prod_Prop!$G:$G=$U5,Prod_Prop!$E:$E=AB$1)),""""))"),"") | AC5: =IF(AB5="","",SUMIFS(Prod_Prop!$J:$J,Prod_Prop!$B:$B,$Q5,Prod_Prop!$H:$H,AB5,Prod_Prop!$I:$I,AC$1)*IF(AB5="Peso",$R5,1)) | AD5: =IF(AB5="","",SUMIFS(Prod_Prop!$J:$J,Prod_Prop!$B:$B,$Q5,Prod_Prop!$H:$H,AB5,Prod_Prop!$I:$I,AD$1)*IF(AB5="Peso",$R5,1))
A6: {=IF(COUNTIF(A$1:A5,Cotizador!F$2)=maxifs(Familias!E:E,Familias!D:D,Cotizador!F$2),IF(COUNTIF(A$1:A5,XLOOKUP(Cotizador!F$2,Implementos!B:B,Implementos!C:C,"",0,1))=SUMIFS(Implementos!D:D,Implementos!B:B,Cotizador!F$2,Implementos!C:C,XLOOKUP(Cotizador!F$2,Implementos!B:B,Implementos!C:C,"",0,1)),"",XLOOKUP(Cotizador!F$2,Implementos!B:B,Implementos!C:C,"",0,1)),Cotizador!F$2)} -> Rodados | B6: =IF(A6="","",COUNTIF(A$1:A6,A6)) -> 1 | C6: {=IF(B6="","",IF(A6=XLOOKUP(A$2,Implementos!B:B,Implementos!C:C,"",0,1),B6+maxifs(B$1:B5,A$1:A5,A$2),B6))} -> 5 | D6: =IF(B6="","", COUNTIFS(Productos!F:F,A6,Productos!H:H,B6)+IF(F6="SI",0,1)) -> 8 | E6: =IFERROR(__xludf.DUMMYFUNCTION("IF($B6="""","""",INDEX(filter(Familias!F:F,Familias!$D:$D=$A6,Familias!$E:$E=$B6),1))"),"O") -> O | F6: =IFERROR(__xludf.DUMMYFUNCTION("IF($B6="""","""",INDEX(filter(Familias!G:G,Familias!$D:$D=$A6,Familias!$E:$E=$B6),1))"),"SI") -> SI | G6: {=IF(C6=1,XLOOKUP(C6,Cotizador!D:D,Cotizador!E:E,"",0,1),"")} | J6: =IF(I6="","",SUMIF(Cotizador!I$1:V$1,I6,Cotizador!I$2:V$2)) | L6: {=IF(COUNTIF(L$1:L5,A$2)=SUMIF(A:A,A$2,D:D),IF(COUNTIF(L$1:L5,XLOOKUP(A$2,Implementos!B:B,Implementos!C:C,"",0,1))=SUMIF(A:A,XLOOKUP(A$2,Implementos!B:B,Implementos!C:C,"",0,1),D:D),"",XLOOKUP(A$2,Implementos!B:B,Implementos!C:C,"",0,1)),A$2)} -> Acoplados Rurales | M6: =IF(L6="","",max(M$1:M5)+1) -> 5 | N6: =IF(L6="","",IF(N5="Orden",1,IF(COUNTIFS(N$1:N5,N5,L$1:L5,L6)=SUMIFS(D:D,B:B,N5,A:A,L6),IF(N5=maxifs(B:B,A:A,L6),"",maxifs(N$1:N5,L$1:L5,L6)+1),N5))) -> 1 | O6: =IF(N6="","",SUMIFS(C:C,B:B,N6,A:A,L6)) -> 1 | P6: =IF(N6="","",COUNTIFS(N$1:N6,N6,L$1:L6,L6)) -> 5 | Q6: =IF(U6="","",SUMIF(Productos!E:E,U6,Productos!A:A)) -> 49 | R6: {=IF(L6="","", max(1,SUMIF(I:I,XLOOKUP(U6,Productos!E:E,Productos!G:G,"",0,1),J:J)))} -> 1 | S6: =IF(Q6="","",IF(SUMIFS(Compat_Vetado!D:D,Compat_Vetado!B:B,SUM(G:G),Compat_Vetado!C:C,Q6)=1,"SI",IF(OR(SUMIF(Cotizador!E:E,Q6,Cotizador!G:G)>0,SUMIFS(Compat_Vetado!D:D,Compat_Vetado!B:B,SUM(G:G),Compat_Vetado!C:C,Q6)=-1),"NO",""))) | T6: =IF(Q6="","",IF(S6="SI","x",IF(S6="NO","",IF(AND(OR(V6="",AND(W6<=SUMIF(I:I,V6,J:J),SUMIF(I:I,V6,J:J)<=X6)),OR(Y6="",AND(Z6<=SUMIF(I:I,Y6,J:J),SUMIF(I:I,Y6,J:J)<=AA6)),OR(AB6="",AND(AC6<=SUMIF(I:I,AB6,J:J),SUMIF(I:I,AB6,J:J)<=AD6))),"x","")))) -> x | U6: =IFERROR(__xludf.DUMMYFUNCTION("IF(P6="""","""",IFERROR(INDEX(filter(Productos!E:E,Productos!F:F=L6,Productos!H:H=N6),P6),IF(M6=SUM(D:D),""Finalizar"",""-"")))"),"Tanque Combustible 2000 lts Standard") -> Tanque Combustible 2000 lts Standard | V6: =IFERROR(__xludf.DUMMYFUNCTION("IF(OR($U6="""",COUNTIF($I:$I,IFERROR(unique(filter(Prod_Prop!$H:$H,Prod_Prop!$G:$G=$U6,Prod_Prop!$E:$E=V$1)),""Check""))=0),"""",IFERROR(unique(filter(Prod_Prop!$H:$H,Prod_Prop!$G:$G=$U6,Prod_Prop!$E:$E=V$1)),""""))"),"") | W6: =IF(V6="","",SUMIFS(Prod_Prop!$J:$J,Prod_Prop!$B:$B,$Q6,Prod_Prop!$H:$H,V6,Prod_Prop!$I:$I,W$1)*IF(V6="Peso",$R6,1)) | X6: =IF(V6="","",SUMIFS(Prod_Prop!$J:$J,Prod_Prop!$B:$B,$Q6,Prod_Prop!$H:$H,V6,Prod_Prop!$I:$I,X$1)*IF(V6="Peso",$R6,1)) | Y6: =IFERROR(__xludf.DUMMYFUNCTION("IF(OR($U6="""",COUNTIF($I:$I,IFERROR(unique(filter(Prod_Prop!$H:$H,Prod_Prop!$G:$G=$U6,Prod_Prop!$E:$E=Y$1)),""Check""))=0),"""",IFERROR(unique(filter(Prod_Prop!$H:$H,Prod_Prop!$G:$G=$U6,Prod_Prop!$E:$E=Y$1)),""""))"),"") | Z6: =IF(Y6="","",SUMIFS(Prod_Prop!$J:$J,Prod_Prop!$B:$B,$Q6,Prod_Prop!$H:$H,Y6,Prod_Prop!$I:$I,Z$1)*IF(Y6="Peso",$R6,1)) | AA6: =IF(Y6="","",SUMIFS(Prod_Prop!$J:$J,Prod_Prop!$B:$B,$Q6,Prod_Prop!$H:$H,Y6,Prod_Prop!$I:$I,AA$1)*IF(Y6="Peso",$R6,1)) | AB6: =IFERROR(__xludf.DUMMYFUNCTION("IF(OR($U6="""",COUNTIF($I:$I,IFERROR(unique(filter(Prod_Prop!$H:$H,Prod_Prop!$G:$G=$U6,Prod_Prop!$E:$E=AB$1)),""Check""))=0),"""",IFERROR(unique(filter(Prod_Prop!$H:$H,Prod_Prop!$G:$G=$U6,Prod_Prop!$E:$E=AB$1)),""""))"),"") | AC6: =IF(AB6="","",SUMIFS(Prod_Prop!$J:$J,Prod_Prop!$B:$B,$Q6,Prod_Prop!$H:$H,AB6,Prod_Prop!$I:$I,AC$1)*IF(AB6="Peso",$R6,1)) | AD6: =IF(AB6="","",SUMIFS(Prod_Prop!$J:$J,Prod_Prop!$B:$B,$Q6,Prod_Prop!$H:$H,AB6,Prod_Prop!$I:$I,AD$1)*IF(AB6="Peso",$R6,1))
A7: {=IF(COUNTIF(A$1:A6,Cotizador!F$2)=maxifs(Familias!E:E,Familias!D:D,Cotizador!F$2),IF(COUNTIF(A$1:A6,XLOOKUP(Cotizador!F$2,Implementos!B:B,Implementos!C:C,"",0,1))=SUMIFS(Implementos!D:D,Implementos!B:B,Cotizador!F$2,Implementos!C:C,XLOOKUP(Cotizador!F$2,Implementos!B:B,Implementos!C:C,"",0,1)),"",XLOOKUP(Cotizador!F$2,Implementos!B:B,Implementos!C:C,"",0,1)),Cotizador!F$2)} -> Rodados | B7: =IF(A7="","",COUNTIF(A$1:A7,A7)) -> 2 | C7: {=IF(B7="","",IF(A7=XLOOKUP(A$2,Implementos!B:B,Implementos!C:C,"",0,1),B7+maxifs(B$1:B6,A$1:A6,A$2),B7))} -> 6 | D7: =IF(B7="","", COUNTIFS(Productos!F:F,A7,Productos!H:H,B7)+IF(F7="SI",0,1)) -> 10 | E7: =IFERROR(__xludf.DUMMYFUNCTION("IF($B7="""","""",INDEX(filter(Familias!F:F,Familias!$D:$D=$A7,Familias!$E:$E=$B7),1))"),"O") -> O | F7: =IFERROR(__xludf.DUMMYFUNCTION("IF($B7="""","""",INDEX(filter(Familias!G:G,Familias!$D:$D=$A7,Familias!$E:$E=$B7),1))"),"SI") -> SI | G7: {=IF(C7=1,XLOOKUP(C7,Cotizador!D:D,Cotizador!E:E,"",0,1),"")} | J7: =IF(I7="","",SUMIF(Cotizador!I$1:V$1,I7,Cotizador!I$2:V$2)) | L7: {=IF(COUNTIF(L$1:L6,A$2)=SUMIF(A:A,A$2,D:D),IF(COUNTIF(L$1:L6,XLOOKUP(A$2,Implementos!B:B,Implementos!C:C,"",0,1))=SUMIF(A:A,XLOOKUP(A$2,Implementos!B:B,Implementos!C:C,"",0,1),D:D),"",XLOOKUP(A$2,Implementos!B:B,Implementos!C:C,"",0,1)),A$2)} -> Acoplados Rurales | M7: =IF(L7="","",max(M$1:M6)+1) -> 6 | N7: =IF(L7="","",IF(N6="Orden",1,IF(COUNTIFS(N$1:N6,N6,L$1:L6,L7)=SUMIFS(D:D,B:B,N6,A:A,L7),IF(N6=maxifs(B:B,A:A,L7),"",maxifs(N$1:N6,L$1:L6,L7)+1),N6))) -> 1 | O7: =IF(N7="","",SUMIFS(C:C,B:B,N7,A:A,L7)) -> 1 | P7: =IF(N7="","",COUNTIFS(N$1:N7,N7,L$1:L7,L7)) -> 6 | Q7: =IF(U7="","",SUMIF(Productos!E:E,U7,Productos!A:A)) -> 50 | R7: {=IF(L7="","", max(1,SUMIF(I:I,XLOOKUP(U7,Productos!E:E,Productos!G:G,"",0,1),J:J)))} -> 1 | S7: =IF(Q7="","",IF(SUMIFS(Compat_Vetado!D:D,Compat_Vetado!B:B,SUM(G:G),Compat_Vetado!C:C,Q7)=1,"SI",IF(OR(SUMIF(Cotizador!E:E,Q7,Cotizador!G:G)>0,SUMIFS(Compat_Vetado!D:D,Compat_Vetado!B:B,SUM(G:G),Compat_Vetado!C:C,Q7)=-1),"NO",""))) | T7: =IF(Q7="","",IF(S7="SI","x",IF(S7="NO","",IF(AND(OR(V7="",AND(W7<=SUMIF(I:I,V7,J:J),SUMIF(I:I,V7,J:J)<=X7)),OR(Y7="",AND(Z7<=SUMIF(I:I,Y7,J:J),SUMIF(I:I,Y7,J:J)<=AA7)),OR(AB7="",AND(AC7<=SUMIF(I:I,AB7,J:J),SUMIF(I:I,AB7,J:J)<=AD7))),"x","")))) -> x | U7: =IFERROR(__xludf.DUMMYFUNCTION("IF(P7="""","""",IFERROR(INDEX(filter(Productos!E:E,Productos!F:F=L7,Productos!H:H=N7),P7),IF(M7=SUM(D:D),""Finalizar"",""-"")))"),"Tanque Combustible 3000 lts Standard") -> Tanque Combustible 3000 lts Standard | V7: =IFERROR(__xludf.DUMMYFUNCTION("IF(OR($U7="""",COUNTIF($I:$I,IFERROR(unique(filter(Prod_Prop!$H:$H,Prod_Prop!$G:$G=$U7,Prod_Prop!$E:$E=V$1)),""Check""))=0),"""",IFERROR(unique(filter(Prod_Prop!$H:$H,Prod_Prop!$G:$G=$U7,Prod_Prop!$E:$E=V$1)),""""))"),"") | W7: =IF(V7="","",SUMIFS(Prod_Prop!$J:$J,Prod_Prop!$B:$B,$Q7,Prod_Prop!$H:$H,V7,Prod_Prop!$I:$I,W$1)*IF(V7="Peso",$R7,1)) | X7: =IF(V7="","",SUMIFS(Prod_Prop!$J:$J,Prod_Prop!$B:$B,$Q7,Prod_Prop!$H:$H,V7,Prod_Prop!$I:$I,X$1)*IF(V7="Peso",$R7,1)) | Y7: =IFERROR(__xludf.DUMMYFUNCTION("IF(OR($U7="""",COUNTIF($I:$I,IFERROR(unique(filter(Prod_Prop!$H:$H,Prod_Prop!$G:$G=$U7,Prod_Prop!$E:$E=Y$1)),""Check""))=0),"""",IFERROR(unique(filter(Prod_Prop!$H:$H,Prod_Prop!$G:$G=$U7,Prod_Prop!$E:$E=Y$1)),""""))"),"") | Z7: =IF(Y7="","",SUMIFS(Prod_Prop!$J:$J,Prod_Prop!$B:$B,$Q7,Prod_Prop!$H:$H,Y7,Prod_Prop!$I:$I,Z$1)*IF(Y7="Peso",$R7,1)) | AA7: =IF(Y7="","",SUMIFS(Prod_Prop!$J:$J,Prod_Prop!$B:$B,$Q7,Prod_Prop!$H:$H,Y7,Prod_Prop!$I:$I,AA$1)*IF(Y7="Peso",$R7,1)) | AB7: =IFERROR(__xludf.DUMMYFUNCTION("IF(OR($U7="""",COUNTIF($I:$I,IFERROR(unique(filter(Prod_Prop!$H:$H,Prod_Prop!$G:$G=$U7,Prod_Prop!$E:$E=AB$1)),""Check""))=0),"""",IFERROR(unique(filter(Prod_Prop!$H:$H,Prod_Prop!$G:$G=$U7,Prod_Prop!$E:$E=AB$1)),""""))"),"") | AC7: =IF(AB7="","",SUMIFS(Prod_Prop!$J:$J,Prod_Prop!$B:$B,$Q7,Prod_Prop!$H:$H,AB7,Prod_Prop!$I:$I,AC$1)*IF(AB7="Peso",$R7,1)) | AD7: =IF(AB7="","",SUMIFS(Prod_Prop!$J:$J,Prod_Prop!$B:$B,$Q7,Prod_Prop!$H:$H,AB7,Prod_Prop!$I:$I,AD$1)*IF(AB7="Peso",$R7,1))
A8: {=IF(COUNTIF(A$1:A7,Cotizador!F$2)=maxifs(Familias!E:E,Familias!D:D,Cotizador!F$2),IF(COUNTIF(A$1:A7,XLOOKUP(Cotizador!F$2,Implementos!B:B,Implementos!C:C,"",0,1))=SUMIFS(Implementos!D:D,Implementos!B:B,Cotizador!F$2,Implementos!C:C,XLOOKUP(Cotizador!F$2,Implementos!B:B,Implementos!C:C,"",0,1)),"",XLOOKUP(Cotizador!F$2,Implementos!B:B,Implementos!C:C,"",0,1)),Cotizador!F$2)} -> Rodados | B8: =IF(A8="","",COUNTIF(A$1:A8,A8)) -> 3 | C8: {=IF(B8="","",IF(A8=XLOOKUP(A$2,Implementos!B:B,Implementos!C:C,"",0,1),B8+maxifs(B$1:B7,A$1:A7,A$2),B8))} -> 7 | D8: =IF(B8="","", COUNTIFS(Productos!F:F,A8,Productos!H:H,B8)+IF(F8="SI",0,1)) -> 8 | E8: =IFERROR(__xludf.DUMMYFUNCTION("IF($B8="""","""",INDEX(filter(Familias!F:F,Familias!$D:$D=$A8,Familias!$E:$E=$B8),1))"),"O") -> O | F8: =IFERROR(__xludf.DUMMYFUNCTION("IF($B8="""","""",INDEX(filter(Familias!G:G,Familias!$D:$D=$A8,Familias!$E:$E=$B8),1))"),"SI") -> SI | G8: {=IF(C8=1,XLOOKUP(C8,Cotizador!D:D,Cotizador!E:E,"",0,1),"")} | J8: =IF(I8="","",SUMIF(Cotizador!I$1:V$1,I8,Cotizador!I$2:V$2)) | L8: {=IF(COUNTIF(L$1:L7,A$2)=SUMIF(A:A,A$2,D:D),IF(COUNTIF(L$1:L7,XLOOKUP(A$2,Implementos!B:B,Implementos!C:C,"",0,1))=SUMIF(A:A,XLOOKUP(A$2,Implementos!B:B,Implementos!C:C,"",0,1),D:D),"",XLOOKUP(A$2,Implementos!B:B,Implementos!C:C,"",0,1)),A$2)} -> Acoplados Rurales | M8: =IF(L8="","",max(M$1:M7)+1) -> 7 | N8: =IF(L8="","",IF(N7="Orden",1,IF(COUNTIFS(N$1:N7,N7,L$1:L7,L8)=SUMIFS(D:D,B:B,N7,A:A,L8),IF(N7=maxifs(B:B,A:A,L8),"",maxifs(N$1:N7,L$1:L7,L8)+1),N7))) -> 1 | O8: =IF(N8="","",SUMIFS(C:C,B:B,N8,A:A,L8)) -> 1 | P8: =IF(N8="","",COUNTIFS(N$1:N8,N8,L$1:L8,L8)) -> 7 | Q8: =IF(U8="","",SUMIF(Productos!E:E,U8,Productos!A:A)) -> 51 | R8: {=IF(L8="","", max(1,SUMIF(I:I,XLOOKUP(U8,Productos!E:E,Productos!G:G,"",0,1),J:J)))} -> 1 | S8: =IF(Q8="","",IF(SUMIFS(Compat_Vetado!D:D,Compat_Vetado!B:B,SUM(G:G),Compat_Vetado!C:C,Q8)=1,"SI",IF(OR(SUMIF(Cotizador!E:E,Q8,Cotizador!G:G)>0,SUMIFS(Compat_Vetado!D:D,Compat_Vetado!B:B,SUM(G:G),Compat_Vetado!C:C,Q8)=-1),"NO",""))) | T8: =IF(Q8="","",IF(S8="SI","x",IF(S8="NO","",IF(AND(OR(V8="",AND(W8<=SUMIF(I:I,V8,J:J),SUMIF(I:I,V8,J:J)<=X8)),OR(Y8="",AND(Z8<=SUMIF(I:I,Y8,J:J),SUMIF(I:I,Y8,J:J)<=AA8)),OR(AB8="",AND(AC8<=SUMIF(I:I,AB8,J:J),SUMIF(I:I,AB8,J:J)<=AD8))),"x","")))) -> x | U8: =IFERROR(__xludf.DUMMYFUNCTION("IF(P8="""","""",IFERROR(INDEX(filter(Productos!E:E,Productos!F:F=L8,Productos!H:H=N8),P8),IF(M8=SUM(D:D),""Finalizar"",""-"")))"),"Tanque Combustible 3000 lts Alto") -> Tanque Combustible 3000 lts Alto | V8: =IFERROR(__xludf.DUMMYFUNCTION("IF(OR($U8="""",COUNTIF($I:$I,IFERROR(unique(filter(Prod_Prop!$H:$H,Prod_Prop!$G:$G=$U8,Prod_Prop!$E:$E=V$1)),""Check""))=0),"""",IFERROR(unique(filter(Prod_Prop!$H:$H,Prod_Prop!$G:$G=$U8,Prod_Prop!$E:$E=V$1)),""""))"),"") | W8: =IF(V8="","",SUMIFS(Prod_Prop!$J:$J,Prod_Prop!$B:$B,$Q8,Prod_Prop!$H:$H,V8,Prod_Prop!$I:$I,W$1)*IF(V8="Peso",$R8,1)) | X8: =IF(V8="","",SUMIFS(Prod_Prop!$J:$J,Prod_Prop!$B:$B,$Q8,Prod_Prop!$H:$H,V8,Prod_Prop!$I:$I,X$1)*IF(V8="Peso",$R8,1)) | Y8: =IFERROR(__xludf.DUMMYFUNCTION("IF(OR($U8="""",COUNTIF($I:$I,IFERROR(unique(filter(Prod_Prop!$H:$H,Prod_Prop!$G:$G=$U8,Prod_Prop!$E:$E=Y$1)),""Check""))=0),"""",IFERROR(unique(filter(Prod_Prop!$H:$H,Prod_Prop!$G:$G=$U8,Prod_Prop!$E:$E=Y$1)),""""))"),"") | Z8: =IF(Y8="","",SUMIFS(Prod_Prop!$J:$J,Prod_Prop!$B:$B,$Q8,Prod_Prop!$H:$H,Y8,Prod_Prop!$I:$I,Z$1)*IF(Y8="Peso",$R8,1)) | AA8: =IF(Y8="","",SUMIFS(Prod_Prop!$J:$J,Prod_Prop!$B:$B,$Q8,Prod_Prop!$H:$H,Y8,Prod_Prop!$I:$I,AA$1)*IF(Y8="Peso",$R8,1)) | AB8: =IFERROR(__xludf.DUMMYFUNCTION("IF(OR($U8="""",COUNTIF($I:$I,IFERROR(unique(filter(Prod_Prop!$H:$H,Prod_Prop!$G:$G=$U8,Prod_Prop!$E:$E=AB$1)),""Check""))=0),"""",IFERROR(unique(filter(Prod_Prop!$H:$H,Prod_Prop!$G:$G=$U8,Prod_Prop!$E:$E=AB$1)),""""))"),"") | AC8: =IF(AB8="","",SUMIFS(Prod_Prop!$J:$J,Prod_Prop!$B:$B,$Q8,Prod_Prop!$H:$H,AB8,Prod_Prop!$I:$I,AC$1)*IF(AB8="Peso",$R8,1)) | AD8: =IF(AB8="","",SUMIFS(Prod_Prop!$J:$J,Prod_Prop!$B:$B,$Q8,Prod_Prop!$H:$H,AB8,Prod_Prop!$I:$I,AD$1)*IF(AB8="Peso",$R8,1))
A9: {=IF(COUNTIF(A$1:A8,Cotizador!F$2)=maxifs(Familias!E:E,Familias!D:D,Cotizador!F$2),IF(COUNTIF(A$1:A8,XLOOKUP(Cotizador!F$2,Implementos!B:B,Implementos!C:C,"",0,1))=SUMIFS(Implementos!D:D,Implementos!B:B,Cotizador!F$2,Implementos!C:C,XLOOKUP(Cotizador!F$2,Implementos!B:B,Implementos!C:C,"",0,1)),"",XLOOKUP(Cotizador!F$2,Implementos!B:B,Implementos!C:C,"",0,1)),Cotizador!F$2)} | B9: =IF(A9="","",COUNTIF(A$1:A9,A9)) | C9: {=IF(B9="","",IF(A9=XLOOKUP(A$2,Implementos!B:B,Implementos!C:C,"",0,1),B9+maxifs(B$1:B8,A$1:A8,A$2),B9))} | D9: =IF(B9="","", COUNTIFS(Productos!F:F,A9,Productos!H:H,B9)+IF(F9="SI",0,1)) | E9: =IFERROR(__xludf.DUMMYFUNCTION("IF($B9="""","""",INDEX(filter(Familias!F:F,Familias!$D:$D=$A9,Familias!$E:$E=$B9),1))"),"") | F9: =IFERROR(__xludf.DUMMYFUNCTION("IF($B9="""","""",INDEX(filter(Familias!G:G,Familias!$D:$D=$A9,Familias!$E:$E=$B9),1))"),"") | G9: {=IF(C9=1,XLOOKUP(C9,Cotizador!D:D,Cotizador!E:E,"",0,1),"")} | J9: =IF(I9="","",SUMIF(Cotizador!I$1:V$1,I9,Cotizador!I$2:V$2)) | L9: {=IF(COUNTIF(L$1:L8,A$2)=SUMIF(A:A,A$2,D:D),IF(COUNTIF(L$1:L8,XLOOKUP(A$2,Implementos!B:B,Implementos!C:C,"",0,1))=SUMIF(A:A,XLOOKUP(A$2,Implementos!B:B,Implementos!C:C,"",0,1),D:D),"",XLOOKUP(A$2,Implementos!B:B,Implementos!C:C,"",0,1)),A$2)} -> Acoplados Rurales | M9: =IF(L9="","",max(M$1:M8)+1) -> 8 | N9: =IF(L9="","",IF(N8="Orden",1,IF(COUNTIFS(N$1:N8,N8,L$1:L8,L9)=SUMIFS(D:D,B:B,N8,A:A,L9),IF(N8=maxifs(B:B,A:A,L9),"",maxifs(N$1:N8,L$1:L8,L9)+1),N8))) -> 1 | O9: =IF(N9="","",SUMIFS(C:C,B:B,N9,A:A,L9)) -> 1 | P9: =IF(N9="","",COUNTIFS(N$1:N9,N9,L$1:L9,L9)) -> 8 | Q9: =IF(U9="","",SUMIF(Productos!E:E,U9,Productos!A:A)) -> 52 | R9: {=IF(L9="","", max(1,SUMIF(I:I,XLOOKUP(U9,Productos!E:E,Productos!G:G,"",0,1),J:J)))} -> 1 | S9: =IF(Q9="","",IF(SUMIFS(Compat_Vetado!D:D,Compat_Vetado!B:B,SUM(G:G),Compat_Vetado!C:C,Q9)=1,"SI",IF(OR(SUMIF(Cotizador!E:E,Q9,Cotizador!G:G)>0,SUMIFS(Compat_Vetado!D:D,Compat_Vetado!B:B,SUM(G:G),Compat_Vetado!C:C,Q9)=-1),"NO",""))) | T9: =IF(Q9="","",IF(S9="SI","x",IF(S9="NO","",IF(AND(OR(V9="",AND(W9<=SUMIF(I:I,V9,J:J),SUMIF(I:I,V9,J:J)<=X9)),OR(Y9="",AND(Z9<=SUMIF(I:I,Y9,J:J),SUMIF(I:I,Y9,J:J)<=AA9)),OR(AB9="",AND(AC9<=SUMIF(I:I,AB9,J:J),SUMIF(I:I,AB9,J:J)<=AD9))),"x","")))) -> x | U9: =IFERROR(__xludf.DUMMYFUNCTION("IF(P9="""","""",IFERROR(INDEX(filter(Productos!E:E,Productos!F:F=L9,Productos!H:H=N9),P9),IF(M9=SUM(D:D),""Finalizar"",""-"")))"),"Tanque Combustible 4000 lts Standard") -> Tanque Combustible 4000 lts Standard | V9: =IFERROR(__xludf.DUMMYFUNCTION("IF(OR($U9="""",COUNTIF($I:$I,IFERROR(unique(filter(Prod_Prop!$H:$H,Prod_Prop!$G:$G=$U9,Prod_Prop!$E:$E=V$1)),""Check""))=0),"""",IFERROR(unique(filter(Prod_Prop!$H:$H,Prod_Prop!$G:$G=$U9,Prod_Prop!$E:$E=V$1)),""""))"),"") | W9: =IF(V9="","",SUMIFS(Prod_Prop!$J:$J,Prod_Prop!$B:$B,$Q9,Prod_Prop!$H:$H,V9,Prod_Prop!$I:$I,W$1)*IF(V9="Peso",$R9,1)) | X9: =IF(V9="","",SUMIFS(Prod_Prop!$J:$J,Prod_Prop!$B:$B,$Q9,Prod_Prop!$H:$H,V9,Prod_Prop!$I:$I,X$1)*IF(V9="Peso",$R9,1)) | Y9: =IFERROR(__xludf.DUMMYFUNCTION("IF(OR($U9="""",COUNTIF($I:$I,IFERROR(unique(filter(Prod_Prop!$H:$H,Prod_Prop!$G:$G=$U9,Prod_Prop!$E:$E=Y$1)),""Check""))=0),"""",IFERROR(unique(filter(Prod_Prop!$H:$H,Prod_Prop!$G:$G=$U9,Prod_Prop!$E:$E=Y$1)),""""))"),"") | Z9: =IF(Y9="","",SUMIFS(Prod_Prop!$J:$J,Prod_Prop!$B:$B,$Q9,Prod_Prop!$H:$H,Y9,Prod_Prop!$I:$I,Z$1)*IF(Y9="Peso",$R9,1)) | AA9: =IF(Y9="","",SUMIFS(Prod_Prop!$J:$J,Prod_Prop!$B:$B,$Q9,Prod_Prop!$H:$H,Y9,Prod_Prop!$I:$I,AA$1)*IF(Y9="Peso",$R9,1)) | AB9: =IFERROR(__xludf.DUMMYFUNCTION("IF(OR($U9="""",COUNTIF($I:$I,IFERROR(unique(filter(Prod_Prop!$H:$H,Prod_Prop!$G:$G=$U9,Prod_Prop!$E:$E=AB$1)),""Check""))=0),"""",IFERROR(unique(filter(Prod_Prop!$H:$H,Prod_Prop!$G:$G=$U9,Prod_Prop!$E:$E=AB$1)),""""))"),"") | AC9: =IF(AB9="","",SUMIFS(Prod_Prop!$J:$J,Prod_Prop!$B:$B,$Q9,Prod_Prop!$H:$H,AB9,Prod_Prop!$I:$I,AC$1)*IF(AB9="Peso",$R9,1)) | AD9: =IF(AB9="","",SUMIFS(Prod_Prop!$J:$J,Prod_Prop!$B:$B,$Q9,Prod_Prop!$H:$H,AB9,Prod_Prop!$I:$I,AD$1)*IF(AB9="Peso",$R9,1))
A10: {=IF(COUNTIF(A$1:A9,Cotizador!F$2)=maxifs(Familias!E:E,Familias!D:D,Cotizador!F$2),IF(COUNTIF(A$1:A9,XLOOKUP(Cotizador!F$2,Implementos!B:B,Implementos!C:C,"",0,1))=SUMIFS(Implementos!D:D,Implementos!B:B,Cotizador!F$2,Implementos!C:C,XLOOKUP(Cotizador!F$2,Implementos!B:B,Implementos!C:C,"",0,1)),"",XLOOKUP(Cotizador!F$2,Implementos!B:B,Implementos!C:C,"",0,1)),Cotizador!F$2)} | B10: =IF(A10="","",COUNTIF(A$1:A10,A10)) | C10: {=IF(B10="","",IF(A10=XLOOKUP(A$2,Implementos!B:B,Implementos!C:C,"",0,1),B10+maxifs(B$1:B9,A$1:A9,A$2),B10))} | D10: =IF(B10="","", COUNTIFS(Productos!F:F,A10,Productos!H:H,B10)+IF(F10="SI",0,1)) | E10: =IFERROR(__xludf.DUMMYFUNCTION("IF($B10="""","""",INDEX(filter(Familias!F:F,Familias!$D:$D=$A10,Familias!$E:$E=$B10),1))"),"") | F10: =IFERROR(__xludf.DUMMYFUNCTION("IF($B10="""","""",INDEX(filter(Familias!G:G,Familias!$D:$D=$A10,Familias!$E:$E=$B10),1))"),"") | G10: {=IF(C10=1,XLOOKUP(C10,Cotizador!D:D,Cotizador!E:E,"",0,1),"")} | J10: =IF(I10="","",SUMIF(Cotizador!I$1:V$1,I10,Cotizador!I$2:V$2)) | L10: {=IF(COUNTIF(L$1:L9,A$2)=SUMIF(A:A,A$2,D:D),IF(COUNTIF(L$1:L9,XLOOKUP(A$2,Implementos!B:B,Implementos!C:C,"",0,1))=SUMIF(A:A,XLOOKUP(A$2,Implementos!B:B,Implementos!C:C,"",0,1),D:D),"",XLOOKUP(A$2,Implementos!B:B,Implementos!C:C,"",0,1)),A$2)} -> Acoplados Rurales | M10: =IF(L10="","",max(M$1:M9)+1) -> 9 | N10: =IF(L10="","",IF(N9="Orden",1,IF(COUNTIFS(N$1:N9,N9,L$1:L9,L10)=SUMIFS(D:D,B:B,N9,A:A,L10),IF(N9=maxifs(B:B,A:A,L10),"",maxifs(N$1:N9,L$1:L9,L10)+1),N9))) -> 1 | O10: =IF(N10="","",SUMIFS(C:C,B:B,N10,A:A,L10)) -> 1 | P10: =IF(N10="","",COUNTIFS(N$1:N10,N10,L$1:L10,L10)) -> 9 | Q10: =IF(U10="","",SUMIF(Productos!E:E,U10,Productos!A:A)) -> 53 | R10: {=IF(L10="","", max(1,SUMIF(I:I,XLOOKUP(U10,Productos!E:E,Productos!G:G,"",0,1),J:J)))} -> 1 | S10: =IF(Q10="","",IF(SUMIFS(Compat_Vetado!D:D,Compat_Vetado!B:B,SUM(G:G),Compat_Vetado!C:C,Q10)=1,"SI",IF(OR(SUMIF(Cotizador!E:E,Q10,Cotizador!G:G)>0,SUMIFS(Compat_Vetado!D:D,Compat_Vetado!B:B,SUM(G:G),Compat_Vetado!C:C,Q10)=-1),"NO",""))) | T10: =IF(Q10="","",IF(S10="SI","x",IF(S10="NO","",IF(AND(OR(V10="",AND(W10<=SUMIF(I:I,V10,J:J),SUMIF(I:I,V10,J:J)<=X10)),OR(Y10="",AND(Z10<=SUMIF(I:I,Y10,J:J),SUMIF(I:I,Y10,J:J)<=AA10)),OR(AB10="",AND(AC10<=SUMIF(I:I,AB10,J:J),SUMIF(I:I,AB10,J:J)<=AD10))),"x","")))) -> x | U10: =IFERROR(__xludf.DUMMYFUNCTION("IF(P10="""","""",IFERROR(INDEX(filter(Productos!E:E,Productos!F:F=L10,Productos!H:H=N10),P10),IF(M10=SUM(D:D),""Finalizar"",""-"")))"),"Tanque Combustible 5000 lts Standard") -> Tanque Combustible 5000 lts Standard | V10: =IFERROR(__xludf.DUMMYFUNCTION("IF(OR($U10="""",COUNTIF($I:$I,IFERROR(unique(filter(Prod_Prop!$H:$H,Prod_Prop!$G:$G=$U10,Prod_Prop!$E:$E=V$1)),""Check""))=0),"""",IFERROR(unique(filter(Prod_Prop!$H:$H,Prod_Prop!$G:$G=$U10,Prod_Prop!$E:$E=V$1)),""""))"),"") | W10: =IF(V10="","",SUMIFS(Prod_Prop!$J:$J,Prod_Prop!$B:$B,$Q10,Prod_Prop!$H:$H,V10,Prod_Prop!$I:$I,W$1)*IF(V10="Peso",$R10,1)) | X10: =IF(V10="","",SUMIFS(Prod_Prop!$J:$J,Prod_Prop!$B:$B,$Q10,Prod_Prop!$H:$H,V10,Prod_Prop!$I:$I,X$1)*IF(V10="Peso",$R10,1)) | Y10: =IFERROR(__xludf.DUMMYFUNCTION("IF(OR($U10="""",COUNTIF($I:$I,IFERROR(unique(filter(Prod_Prop!$H:$H,Prod_Prop!$G:$G=$U10,Prod_Prop!$E:$E=Y$1)),""Check""))=0),"""",IFERROR(unique(filter(Prod_Prop!$H:$H,Prod_Prop!$G:$G=$U10,Prod_Prop!$E:$E=Y$1)),""""))"),"") | Z10: =IF(Y10="","",SUMIFS(Prod_Prop!$J:$J,Prod_Prop!$B:$B,$Q10,Prod_Prop!$H:$H,Y10,Prod_Prop!$I:$I,Z$1)*IF(Y10="Peso",$R10,1)) | AA10: =IF(Y10="","",SUMIFS(Prod_Prop!$J:$J,Prod_Prop!$B:$B,$Q10,Prod_Prop!$H:$H,Y10,Prod_Prop!$I:$I,AA$1)*IF(Y10="Peso",$R10,1)) | AB10: =IFERROR(__xludf.DUMMYFUNCTION("IF(OR($U10="""",COUNTIF($I:$I,IFERROR(unique(filter(Prod_Prop!$H:$H,Prod_Prop!$G:$G=$U10,Prod_Prop!$E:$E=AB$1)),""Check""))=0),"""",IFERROR(unique(filter(Prod_Prop!$H:$H,Prod_Prop!$G:$G=$U10,Prod_Prop!$E:$E=AB$1)),""""))"),"") | AC10: =IF(AB10="","",SUMIFS(Prod_Prop!$J:$J,Prod_Prop!$B:$B,$Q10,Prod_Prop!$H:$H,AB10,Prod_Prop!$I:$I,AC$1)*IF(AB10="Peso",$R10,1)) | AD10: =IF(AB10="","",SUMIFS(Prod_Prop!$J:$J,Prod_Prop!$B:$B,$Q10,Prod_Prop!$H:$H,AB10,Prod_Prop!$I:$I,AD$1)*IF(AB10="Peso",$R10,1))
A11: {=IF(COUNTIF(A$1:A10,Cotizador!F$2)=maxifs(Familias!E:E,Familias!D:D,Cotizador!F$2),IF(COUNTIF(A$1:A10,XLOOKUP(Cotizador!F$2,Implementos!B:B,Implementos!C:C,"",0,1))=SUMIFS(Implementos!D:D,Implementos!B:B,Cotizador!F$2,Implementos!C:C,XLOOKUP(Cotizador!F$2,Implementos!B:B,Implementos!C:C,"",0,1)),"",XLOOKUP(Cotizador!F$2,Implementos!B:B,Implementos!C:C,"",0,1)),Cotizador!F$2)} | B11: =IF(A11="","",COUNTIF(A$1:A11,A11)) | C11: {=IF(B11="","",IF(A11=XLOOKUP(A$2,Implementos!B:B,Implementos!C:C,"",0,1),B11+maxifs(B$1:B10,A$1:A10,A$2),B11))} | D11: =IF(B11="","", COUNTIFS(Productos!F:F,A11,Productos!H:H,B11)+IF(F11="SI",0,1)) | E11: =IFERROR(__xludf.DUMMYFUNCTION("IF($B11="""","""",INDEX(filter(Familias!F:F,Familias!$D:$D=$A11,Familias!$E:$E=$B11),1))"),"") | F11: =IFERROR(__xludf.DUMMYFUNCTION("IF($B11="""","""",INDEX(filter(Familias!G:G,Familias!$D:$D=$A11,Familias!$E:$E=$B11),1))"),"") | G11: {=IF(C11=1,XLOOKUP(C11,Cotizador!D:D,Cotizador!E:E,"",0,1),"")} | J11: =IF(I11="","",SUMIF(Cotizador!I$1:V$1,I11,Cotizador!I$2:V$2)) | L11: {=IF(COUNTIF(L$1:L10,A$2)=SUMIF(A:A,A$2,D:D),IF(COUNTIF(L$1:L10,XLOOKUP(A$2,Implementos!B:B,Implementos!C:C,"",0,1))=SUMIF(A:A,XLOOKUP(A$2,Implementos!B:B,Implementos!C:C,"",0,1),D:D),"",XLOOKUP(A$2,Implementos!B:B,Implementos!C:C,"",0,1)),A$2)} -> Acoplados Rurales | M11: =IF(L11="","",max(M$1:M10)+1) -> 10 | N11: =IF(L11="","",IF(N10="Orden",1,IF(COUNTIFS(N$1:N10,N10,L$1:L10,L11)=SUMIFS(D:D,B:B,N10,A:A,L11),IF(N10=maxifs(B:B,A:A,L11),"",maxifs(N$1:N10,L$1:L10,L11)+1),N10))) -> 1 | O11: =IF(N11="","",SUMIFS(C:C,B:B,N11,A:A,L11)) -> 1 | P11: =IF(N11="","",COUNTIFS(N$1:N11,N11,L$1:L11,L11)) -> 10 | Q11: =IF(U11="","",SUMIF(Productos!E:E,U11,Productos!A:A)) -> 54 | R11: {=IF(L11="","", max(1,SUMIF(I:I,XLOOKUP(U11,Productos!E:E,Productos!G:G,"",0,1),J:J)))} -> 1 | S11: =IF(Q11="","",IF(SUMIFS(Compat_Vetado!D:D,Compat_Vetado!B:B,SUM(G:G),Compat_Vetado!C:C,Q11)=1,"SI",IF(OR(SUMIF(Cotizador!E:E,Q11,Cotizador!G:G)>0,SUMIFS(Compat_Vetado!D:D,Compat_Vetado!B:B,SUM(G:G),Compat_Vetado!C:C,Q11)=-1),"NO",""))) | T11: =IF(Q11="","",IF(S11="SI","x",IF(S11="NO","",IF(AND(OR(V11="",AND(W11<=SUMIF(I:I,V11,J:J),SUMIF(I:I,V11,J:J)<=X11)),OR(Y11="",AND(Z11<=SUMIF(I:I,Y11,J:J),SUMIF(I:I,Y11,J:J)<=AA11)),OR(AB11="",AND(AC11<=SUMIF(I:I,AB11,J:J),SUMIF(I:I,AB11,J:J)<=AD11))),"x","")))) -> x | U11: =IFERROR(__xludf.DUMMYFUNCTION("IF(P11="""","""",IFERROR(INDEX(filter(Productos!E:E,Productos!F:F=L11,Productos!H:H=N11),P11),IF(M11=SUM(D:D),""Finalizar"",""-"")))"),"Tanque Combustible 5000 lts Alto") -> Tanque Combustible 5000 lts Alto | V11: =IFERROR(__xludf.DUMMYFUNCTION("IF(OR($U11="""",COUNTIF($I:$I,IFERROR(unique(filter(Prod_Prop!$H:$H,Prod_Prop!$G:$G=$U11,Prod_Prop!$E:$E=V$1)),""Check""))=0),"""",IFERROR(unique(filter(Prod_Prop!$H:$H,Prod_Prop!$G:$G=$U11,Prod_Prop!$E:$E=V$1)),""""))"),"") | W11: =IF(V11="","",SUMIFS(Prod_Prop!$J:$J,Prod_Prop!$B:$B,$Q11,Prod_Prop!$H:$H,V11,Prod_Prop!$I:$I,W$1)*IF(V11="Peso",$R11,1)) | X11: =IF(V11="","",SUMIFS(Prod_Prop!$J:$J,Prod_Prop!$B:$B,$Q11,Prod_Prop!$H:$H,V11,Prod_Prop!$I:$I,X$1)*IF(V11="Peso",$R11,1)) | Y11: =IFERROR(__xludf.DUMMYFUNCTION("IF(OR($U11="""",COUNTIF($I:$I,IFERROR(unique(filter(Prod_Prop!$H:$H,Prod_Prop!$G:$G=$U11,Prod_Prop!$E:$E=Y$1)),""Check""))=0),"""",IFERROR(unique(filter(Prod_Prop!$H:$H,Prod_Prop!$G:$G=$U11,Prod_Prop!$E:$E=Y$1)),""""))"),"") | Z11: =IF(Y11="","",SUMIFS(Prod_Prop!$J:$J,Prod_Prop!$B:$B,$Q11,Prod_Prop!$H:$H,Y11,Prod_Prop!$I:$I,Z$1)*IF(Y11="Peso",$R11,1)) | AA11: =IF(Y11="","",SUMIFS(Prod_Prop!$J:$J,Prod_Prop!$B:$B,$Q11,Prod_Prop!$H:$H,Y11,Prod_Prop!$I:$I,AA$1)*IF(Y11="Peso",$R11,1)) | AB11: =IFERROR(__xludf.DUMMYFUNCTION("IF(OR($U11="""",COUNTIF($I:$I,IFERROR(unique(filter(Prod_Prop!$H:$H,Prod_Prop!$G:$G=$U11,Prod_Prop!$E:$E=AB$1)),""Check""))=0),"""",IFERROR(unique(filter(Prod_Prop!$H:$H,Prod_Prop!$G:$G=$U11,Prod_Prop!$E:$E=AB$1)),""""))"),"") | AC11: =IF(AB11="","",SUMIFS(Prod_Prop!$J:$J,Prod_Prop!$B:$B,$Q11,Prod_Prop!$H:$H,AB11,Prod_Prop!$I:$I,AC$1)*IF(AB11="Peso",$R11,1)) | AD11: =IF(AB11="","",SUMIFS(Prod_Prop!$J:$J,Prod_Prop!$B:$B,$Q11,Prod_Prop!$H:$H,AB11,Prod_Prop!$I:$I,AD$1)*IF(AB11="Peso",$R11,1))
A12: {=IF(COUNTIF(A$1:A11,Cotizador!F$2)=maxifs(Familias!E:E,Familias!D:D,Cotizador!F$2),IF(COUNTIF(A$1:A11,XLOOKUP(Cotizador!F$2,Implementos!B:B,Implementos!C:C,"",0,1))=SUMIFS(Implementos!D:D,Implementos!B:B,Cotizador!F$2,Implementos!C:C,XLOOKUP(Cotizador!F$2,Implementos!B:B,Implementos!C:C,"",0,1)),"",XLOOKUP(Cotizador!F$2,Implementos!B:B,Implementos!C:C,"",0,1)),Cotizador!F$2)} | B12: =IF(A12="","",COUNTIF(A$1:A12,A12)) | C12: {=IF(B12="","",IF(A12=XLOOKUP(A$2,Implementos!B:B,Implementos!C:C,"",0,1),B12+maxifs(B$1:B11,A$1:A11,A$2),B12))} | D12: =IF(B12="","", COUNTIFS(Productos!F:F,A12,Productos!H:H,B12)+IF(F12="SI",0,1)) | E12: =IFERROR(__xludf.DUMMYFUNCTION("IF($B12="""","""",INDEX(filter(Familias!F:F,Familias!$D:$D=$A12,Familias!$E:$E=$B12),1))"),"") | F12: =IFERROR(__xludf.DUMMYFUNCTION("IF($B12="""","""",INDEX(filter(Familias!G:G,Familias!$D:$D=$A12,Familias!$E:$E=$B12),1))"),"") | G12: {=IF(C12=1,XLOOKUP(C12,Cotizador!D:D,Cotizador!E:E,"",0,1),"")} | J12: =IF(I12="","",SUMIF(Cotizador!I$1:V$1,I12,Cotizador!I$2:V$2)) | L12: {=IF(COUNTIF(L$1:L11,A$2)=SUMIF(A:A,A$2,D:D),IF(COUNTIF(L$1:L11,XLOOKUP(A$2,Implementos!B:B,Implementos!C:C,"",0,1))=SUMIF(A:A,XLOOKUP(A$2,Implementos!B:B,Implementos!C:C,"",0,1),D:D),"",XLOOKUP(A$2,Implementos!B:B,Implementos!C:C,"",0,1)),A$2)} -> Acoplados Rurales | M12: =IF(L12="","",max(M$1:M11)+1) -> 11 | N12: =IF(L12="","",IF(N11="Orden",1,IF(COUNTIFS(N$1:N11,N11,L$1:L11,L12)=SUMIFS(D:D,B:B,N11,A:A,L12),IF(N11=maxifs(B:B,A:A,L12),"",maxifs(N$1:N11,L$1:L11,L12)+1),N11))) -> 1 | O12: =IF(N12="","",SUMIFS(C:C,B:B,N12,A:A,L12)) -> 1 | P12: =IF(N12="","",COUNTIFS(N$1:N12,N12,L$1:L12,L12)) -> 11 | Q12: =IF(U12="","",SUMIF(Productos!E:E,U12,Productos!A:A)) -> 55 | R12: {=IF(L12="","", max(1,SUMIF(I:I,XLOOKUP(U12,Productos!E:E,Productos!G:G,"",0,1),J:J)))} -> 1 | S12: =IF(Q12="","",IF(SUMIFS(Compat_Vetado!D:D,Compat_Vetado!B:B,SUM(G:G),Compat_Vetado!C:C,Q12)=1,"SI",IF(OR(SUMIF(Cotizador!E:E,Q12,Cotizador!G:G)>0,SUMIFS(Compat_Vetado!D:D,Compat_Vetado!B:B,SUM(G:G),Compat_Vetado!C:C,Q12)=-1),"NO",""))) | T12: =IF(Q12="","",IF(S12="SI","x",IF(S12="NO","",IF(AND(OR(V12="",AND(W12<=SUMIF(I:I,V12,J:J),SUMIF(I:I,V12,J:J)<=X12)),OR(Y12="",AND(Z12<=SUMIF(I:I,Y12,J:J),SUMIF(I:I,Y12,J:J)<=AA12)),OR(AB12="",AND(AC12<=SUMIF(I:I,AB12,J:J),SUMIF(I:I,AB12,J:J)<=AD12))),"x","")))) -> x | U12: =IFERROR(__xludf.DUMMYFUNCTION("IF(P12="""","""",IFERROR(INDEX(filter(Productos!E:E,Productos!F:F=L12,Productos!H:H=N12),P12),IF(M12=SUM(D:D),""Finalizar"",""-"")))"),"Tanque Combustible 2000 lts Alto") -> Tanque Combustible 2000 lts Alto | V12: =IFERROR(__xludf.DUMMYFUNCTION("IF(OR($U12="""",COUNTIF($I:$I,IFERROR(unique(filter(Prod_Prop!$H:$H,Prod_Prop!$G:$G=$U12,Prod_Prop!$E:$E=V$1)),""Check""))=0),"""",IFERROR(unique(filter(Prod_Prop!$H:$H,Prod_Prop!$G:$G=$U12,Prod_Prop!$E:$E=V$1)),""""))"),"") | W12: =IF(V12="","",SUMIFS(Prod_Prop!$J:$J,Prod_Prop!$B:$B,$Q12,Prod_Prop!$H:$H,V12,Prod_Prop!$I:$I,W$1)*IF(V12="Peso",$R12,1)) | X12: =IF(V12="","",SUMIFS(Prod_Prop!$J:$J,Prod_Prop!$B:$B,$Q12,Prod_Prop!$H:$H,V12,Prod_Prop!$I:$I,X$1)*IF(V12="Peso",$R12,1)) | Y12: =IFERROR(__xludf.DUMMYFUNCTION("IF(OR($U12="""",COUNTIF($I:$I,IFERROR(unique(filter(Prod_Prop!$H:$H,Prod_Prop!$G:$G=$U12,Prod_Prop!$E:$E=Y$1)),""Check""))=0),"""",IFERROR(unique(filter(Prod_Prop!$H:$H,Prod_Prop!$G:$G=$U12,Prod_Prop!$E:$E=Y$1)),""""))"),"") | Z12: =IF(Y12="","",SUMIFS(Prod_Prop!$J:$J,Prod_Prop!$B:$B,$Q12,Prod_Prop!$H:$H,Y12,Prod_Prop!$I:$I,Z$1)*IF(Y12="Peso",$R12,1)) | AA12: =IF(Y12="","",SUMIFS(Prod_Prop!$J:$J,Prod_Prop!$B:$B,$Q12,Prod_Prop!$H:$H,Y12,Prod_Prop!$I:$I,AA$1)*IF(Y12="Peso",$R12,1)) | AB12: =IFERROR(__xludf.DUMMYFUNCTION("IF(OR($U12="""",COUNTIF($I:$I,IFERROR(unique(filter(Prod_Prop!$H:$H,Prod_Prop!$G:$G=$U12,Prod_Prop!$E:$E=AB$1)),""Check""))=0),"""",IFERROR(unique(filter(Prod_Prop!$H:$H,Prod_Prop!$G:$G=$U12,Prod_Prop!$E:$E=AB$1)),""""))"),"") | AC12: =IF(AB12="","",SUMIFS(Prod_Prop!$J:$J,Prod_Prop!$B:$B,$Q12,Prod_Prop!$H:$H,AB12,Prod_Prop!$I:$I,AC$1)*IF(AB12="Peso",$R12,1)) | AD12: =IF(AB12="","",SUMIFS(Prod_Prop!$J:$J,Prod_Prop!$B:$B,$Q12,Prod_Prop!$H:$H,AB12,Prod_Prop!$I:$I,AD$1)*IF(AB12="Peso",$R12,1))
A13: {=IF(COUNTIF(A$1:A12,Cotizador!F$2)=maxifs(Familias!E:E,Familias!D:D,Cotizador!F$2),IF(COUNTIF(A$1:A12,XLOOKUP(Cotizador!F$2,Implementos!B:B,Implementos!C:C,"",0,1))=SUMIFS(Implementos!D:D,Implementos!B:B,Cotizador!F$2,Implementos!C:C,XLOOKUP(Cotizador!F$2,Implementos!B:B,Implementos!C:C,"",0,1)),"",XLOOKUP(Cotizador!F$2,Implementos!B:B,Implementos!C:C,"",0,1)),Cotizador!F$2)} | B13: =IF(A13="","",COUNTIF(A$1:A13,A13)) | C13: {=IF(B13="","",IF(A13=XLOOKUP(A$2,Implementos!B:B,Implementos!C:C,"",0,1),B13+maxifs(B$1:B12,A$1:A12,A$2),B13))} | D13: =IF(B13="","", COUNTIFS(Productos!F:F,A13,Productos!H:H,B13)+IF(F13="SI",0,1)) | E13: =IFERROR(__xludf.DUMMYFUNCTION("IF($B13="""","""",INDEX(filter(Familias!F:F,Familias!$D:$D=$A13,Familias!$E:$E=$B13),1))"),"") | F13: =IFERROR(__xludf.DUMMYFUNCTION("IF($B13="""","""",INDEX(filter(Familias!G:G,Familias!$D:$D=$A13,Familias!$E:$E=$B13),1))"),"") | G13: {=IF(C13=1,XLOOKUP(C13,Cotizador!D:D,Cotizador!E:E,"",0,1),"")} | J13: =IF(I13="","",SUMIF(Cotizador!I$1:V$1,I13,Cotizador!I$2:V$2)) | L13: {=IF(COUNTIF(L$1:L12,A$2)=SUMIF(A:A,A$2,D:D),IF(COUNTIF(L$1:L12,XLOOKUP(A$2,Implementos!B:B,Implementos!C:C,"",0,1))=SUMIF(A:A,XLOOKUP(A$2,Implementos!B:B,Implementos!C:C,"",0,1),D:D),"",XLOOKUP(A$2,Implementos!B:B,Implementos!C:C,"",0,1)),A$2)} -> Acoplados Rurales | M13: =IF(L13="","",max(M$1:M12)+1) -> 12 | N13: =IF(L13="","",IF(N12="Orden",1,IF(COUNTIFS(N$1:N12,N12,L$1:L12,L13)=SUMIFS(D:D,B:B,N12,A:A,L13),IF(N12=maxifs(B:B,A:A,L13),"",maxifs(N$1:N12,L$1:L12,L13)+1),N12))) -> 1 | O13: =IF(N13="","",SUMIFS(C:C,B:B,N13,A:A,L13)) -> 1 | P13: =IF(N13="","",COUNTIFS(N$1:N13,N13,L$1:L13,L13)) -> 12 | Q13: =IF(U13="","",SUMIF(Productos!E:E,U13,Productos!A:A)) -> 56 | R13: {=IF(L13="","", max(1,SUMIF(I:I,XLOOKUP(U13,Productos!E:E,Productos!G:G,"",0,1),J:J)))} -> 1 | S13: =IF(Q13="","",IF(SUMIFS(Compat_Vetado!D:D,Compat_Vetado!B:B,SUM(G:G),Compat_Vetado!C:C,Q13)=1,"SI",IF(OR(SUMIF(Cotizador!E:E,Q13,Cotizador!G:G)>0,SUMIFS(Compat_Vetado!D:D,Compat_Vetado!B:B,SUM(G:G),Compat_Vetado!C:C,Q13)=-1),"NO",""))) -> NO | T13: =IF(Q13="","",IF(S13="SI","x",IF(S13="NO","",IF(AND(OR(V13="",AND(W13<=SUMIF(I:I,V13,J:J),SUMIF(I:I,V13,J:J)<=X13)),OR(Y13="",AND(Z13<=SUMIF(I:I,Y13,J:J),SUMIF(I:I,Y13,J:J)<=AA13)),OR(AB13="",AND(AC13<=SUMIF(I:I,AB13,J:J),SUMIF(I:I,AB13,J:J)<=AD13))),"x","")))) | U13: =IFERROR(__xludf.DUMMYFUNCTION("IF(P13="""","""",IFERROR(INDEX(filter(Productos!E:E,Productos!F:F=L13,Productos!H:H=N13),P13),IF(M13=SUM(D:D),""Finalizar"",""-"")))"),"Tanque Combustible 4000 lts Alto") -> Tanque Combustible 4000 lts Alto | V13: =IFERROR(__xludf.DUMMYFUNCTION("IF(OR($U13="""",COUNTIF($I:$I,IFERROR(unique(filter(Prod_Prop!$H:$H,Prod_Prop!$G:$G=$U13,Prod_Prop!$E:$E=V$1)),""Check""))=0),"""",IFERROR(unique(filter(Prod_Prop!$H:$H,Prod_Prop!$G:$G=$U13,Prod_Prop!$E:$E=V$1)),""""))"),"") | W13: =IF(V13="","",SUMIFS(Prod_Prop!$J:$J,Prod_Prop!$B:$B,$Q13,Prod_Prop!$H:$H,V13,Prod_Prop!$I:$I,W$1)*IF(V13="Peso",$R13,1)) | X13: =IF(V13="","",SUMIFS(Prod_Prop!$J:$J,Prod_Prop!$B:$B,$Q13,Prod_Prop!$H:$H,V13,Prod_Prop!$I:$I,X$1)*IF(V13="Peso",$R13,1)) | Y13: =IFERROR(__xludf.DUMMYFUNCTION("IF(OR($U13="""",COUNTIF($I:$I,IFERROR(unique(filter(Prod_Prop!$H:$H,Prod_Prop!$G:$G=$U13,Prod_Prop!$E:$E=Y$1)),""Check""))=0),"""",IFERROR(unique(filter(Prod_Prop!$H:$H,Prod_Prop!$G:$G=$U13,Prod_Prop!$E:$E=Y$1)),""""))"),"") | Z13: =IF(Y13="","",SUMIFS(Prod_Prop!$J:$J,Prod_Prop!$B:$B,$Q13,Prod_Prop!$H:$H,Y13,Prod_Prop!$I:$I,Z$1)*IF(Y13="Peso",$R13,1)) | AA13: =IF(Y13="","",SUMIFS(Prod_Prop!$J:$J,Prod_Prop!$B:$B,$Q13,Prod_Prop!$H:$H,Y13,Prod_Prop!$I:$I,AA$1)*IF(Y13="Peso",$R13,1)) | AB13: =IFERROR(__xludf.DUMMYFUNCTION("IF(OR($U13="""",COUNTIF($I:$I,IFERROR(unique(filter(Prod_Prop!$H:$H,Prod_Prop!$G:$G=$U13,Prod_Prop!$E:$E=AB$1)),""Check""))=0),"""",IFERROR(unique(filter(Prod_Prop!$H:$H,Prod_Prop!$G:$G=$U13,Prod_Prop!$E:$E=AB$1)),""""))"),"") | AC13: =IF(AB13="","",SUMIFS(Prod_Prop!$J:$J,Prod_Prop!$B:$B,$Q13,Prod_Prop!$H:$H,AB13,Prod_Prop!$I:$I,AC$1)*IF(AB13="Peso",$R13,1)) | AD13: =IF(AB13="","",SUMIFS(Prod_Prop!$J:$J,Prod_Prop!$B:$B,$Q13,Prod_Prop!$H:$H,AB13,Prod_Prop!$I:$I,AD$1)*IF(AB13="Peso",$R13,1))
A14: {=IF(COUNTIF(A$1:A13,Cotizador!F$2)=maxifs(Familias!E:E,Familias!D:D,Cotizador!F$2),IF(COUNTIF(A$1:A13,XLOOKUP(Cotizador!F$2,Implementos!B:B,Implementos!C:C,"",0,1))=SUMIFS(Implementos!D:D,Implementos!B:B,Cotizador!F$2,Implementos!C:C,XLOOKUP(Cotizador!F$2,Implementos!B:B,Implementos!C:C,"",0,1)),"",XLOOKUP(Cotizador!F$2,Implementos!B:B,Implementos!C:C,"",0,1)),Cotizador!F$2)} | B14: =IF(A14="","",COUNTIF(A$1:A14,A14)) | C14: {=IF(B14="","",IF(A14=XLOOKUP(A$2,Implementos!B:B,Implementos!C:C,"",0,1),B14+maxifs(B$1:B13,A$1:A13,A$2),B14))} | D14: =IF(B14="","", COUNTIFS(Productos!F:F,A14,Productos!H:H,B14)+IF(F14="SI",0,1)) | E14: =IFERROR(__xludf.DUMMYFUNCTION("IF($B14="""","""",INDEX(filter(Familias!F:F,Familias!$D:$D=$A14,Familias!$E:$E=$B14),1))"),"") | F14: =IFERROR(__xludf.DUMMYFUNCTION("IF($B14="""","""",INDEX(filter(Familias!G:G,Familias!$D:$D=$A14,Familias!$E:$E=$B14),1))"),"") | G14: {=IF(C14=1,XLOOKUP(C14,Cotizador!D:D,Cotizador!E:E,"",0,1),"")} | J14: =IF(I14="","",SUMIF(Cotizador!I$1:V$1,I14,Cotizador!I$2:V$2)) | L14: {=IF(COUNTIF(L$1:L13,A$2)=SUMIF(A:A,A$2,D:D),IF(COUNTIF(L$1:L13,XLOOKUP(A$2,Implementos!B:B,Implementos!C:C,"",0,1))=SUMIF(A:A,XLOOKUP(A$2,Implementos!B:B,Implementos!C:C,"",0,1),D:D),"",XLOOKUP(A$2,Implementos!B:B,Implementos!C:C,"",0,1)),A$2)} -> Acoplados Rurales | M14: =IF(L14="","",max(M$1:M13)+1) -> 13 | N14: =IF(L14="","",IF(N13="Orden",1,IF(COUNTIFS(N$1:N13,N13,L$1:L13,L14)=SUMIFS(D:D,B:B,N13,A:A,L14),IF(N13=maxifs(B:B,A:A,L14),"",maxifs(N$1:N13,L$1:L13,L14)+1),N13))) -> 1 | O14: =IF(N14="","",SUMIFS(C:C,B:B,N14,A:A,L14)) -> 1 | P14: =IF(N14="","",COUNTIFS(N$1:N14,N14,L$1:L14,L14)) -> 13 | Q14: =IF(U14="","",SUMIF(Productos!E:E,U14,Productos!A:A)) -> 92 | R14: {=IF(L14="","", max(1,SUMIF(I:I,XLOOKUP(U14,Productos!E:E,Productos!G:G,"",0,1),J:J)))} -> 1 | S14: =IF(Q14="","",IF(SUMIFS(Compat_Vetado!D:D,Compat_Vetado!B:B,SUM(G:G),Compat_Vetado!C:C,Q14)=1,"SI",IF(OR(SUMIF(Cotizador!E:E,Q14,Cotizador!G:G)>0,SUMIFS(Compat_Vetado!D:D,Compat_Vetado!B:B,SUM(G:G),Compat_Vetado!C:C,Q14)=-1),"NO",""))) -> NO | T14: =IF(Q14="","",IF(S14="SI","x",IF(S14="NO","",IF(AND(OR(V14="",AND(W14<=SUMIF(I:I,V14,J:J),SUMIF(I:I,V14,J:J)<=X14)),OR(Y14="",AND(Z14<=SUMIF(I:I,Y14,J:J),SUMIF(I:I,Y14,J:J)<=AA14)),OR(AB14="",AND(AC14<=SUMIF(I:I,AB14,J:J),SUMIF(I:I,AB14,J:J)<=AD14))),"x","")))) | U14: =IFERROR(__xludf.DUMMYFUNCTION("IF(P14="""","""",IFERROR(INDEX(filter(Productos!E:E,Productos!F:F=L14,Productos!H:H=N14),P14),IF(M14=SUM(D:D),""Finalizar"",""-"")))"),"Tanque Plastico Horizontal 750 Lts") -> Tanque Plastico Horizontal 750 Lts | V14: =IFERROR(__xludf.DUMMYFUNCTION("IF(OR($U14="""",COUNTIF($I:$I,IFERROR(unique(filter(Prod_Prop!$H:$H,Prod_Prop!$G:$G=$U14,Prod_Prop!$E:$E=V$1)),""Check""))=0),"""",IFERROR(unique(filter(Prod_Prop!$H:$H,Prod_Prop!$G:$G=$U14,Prod_Prop!$E:$E=V$1)),""""))"),"") | W14: =IF(V14="","",SUMIFS(Prod_Prop!$J:$J,Prod_Prop!$B:$B,$Q14,Prod_Prop!$H:$H,V14,Prod_Prop!$I:$I,W$1)*IF(V14="Peso",$R14,1)) | X14: =IF(V14="","",SUMIFS(Prod_Prop!$J:$J,Prod_Prop!$B:$B,$Q14,Prod_Prop!$H:$H,V14,Prod_Prop!$I:$I,X$1)*IF(V14="Peso",$R14,1)) | Y14: =IFERROR(__xludf.DUMMYFUNCTION("IF(OR($U14="""",COUNTIF($I:$I,IFERROR(unique(filter(Prod_Prop!$H:$H,Prod_Prop!$G:$G=$U14,Prod_Prop!$E:$E=Y$1)),""Check""))=0),"""",IFERROR(unique(filter(Prod_Prop!$H:$H,Prod_Prop!$G:$G=$U14,Prod_Prop!$E:$E=Y$1)),""""))"),"") | Z14: =IF(Y14="","",SUMIFS(Prod_Prop!$J:$J,Prod_Prop!$B:$B,$Q14,Prod_Prop!$H:$H,Y14,Prod_Prop!$I:$I,Z$1)*IF(Y14="Peso",$R14,1)) | AA14: =IF(Y14="","",SUMIFS(Prod_Prop!$J:$J,Prod_Prop!$B:$B,$Q14,Prod_Prop!$H:$H,Y14,Prod_Prop!$I:$I,AA$1)*IF(Y14="Peso",$R14,1)) | AB14: =IFERROR(__xludf.DUMMYFUNCTION("IF(OR($U14="""",COUNTIF($I:$I,IFERROR(unique(filter(Prod_Prop!$H:$H,Prod_Prop!$G:$G=$U14,Prod_Prop!$E:$E=AB$1)),""Check""))=0),"""",IFERROR(unique(filter(Prod_Prop!$H:$H,Prod_Prop!$G:$G=$U14,Prod_Prop!$E:$E=AB$1)),""""))"),"") | AC14: =IF(AB14="","",SUMIFS(Prod_Prop!$J:$J,Prod_Prop!$B:$B,$Q14,Prod_Prop!$H:$H,AB14,Prod_Prop!$I:$I,AC$1)*IF(AB14="Peso",$R14,1)) | AD14: =IF(AB14="","",SUMIFS(Prod_Prop!$J:$J,Prod_Prop!$B:$B,$Q14,Prod_Prop!$H:$H,AB14,Prod_Prop!$I:$I,AD$1)*IF(AB14="Peso",$R14,1))
A15: {=IF(COUNTIF(A$1:A14,Cotizador!F$2)=maxifs(Familias!E:E,Familias!D:D,Cotizador!F$2),IF(COUNTIF(A$1:A14,XLOOKUP(Cotizador!F$2,Implementos!B:B,Implementos!C:C,"",0,1))=SUMIFS(Implementos!D:D,Implementos!B:B,Cotizador!F$2,Implementos!C:C,XLOOKUP(Cotizador!F$2,Implementos!B:B,Implementos!C:C,"",0,1)),"",XLOOKUP(Cotizador!F$2,Implementos!B:B,Implementos!C:C,"",0,1)),Cotizador!F$2)} | B15: =IF(A15="","",COUNTIF(A$1:A15,A15)) | C15: {=IF(B15="","",IF(A15=XLOOKUP(A$2,Implementos!B:B,Implementos!C:C,"",0,1),B15+maxifs(B$1:B14,A$1:A14,A$2),B15))} | D15: =IF(B15="","", COUNTIFS(Productos!F:F,A15,Productos!H:H,B15)+IF(F15="SI",0,1)) | E15: =IFERROR(__xludf.DUMMYFUNCTION("IF($B15="""","""",INDEX(filter(Familias!F:F,Familias!$D:$D=$A15,Familias!$E:$E=$B15),1))"),"") | F15: =IFERROR(__xludf.DUMMYFUNCTION("IF($B15="""","""",INDEX(filter(Familias!G:G,Familias!$D:$D=$A15,Familias!$E:$E=$B15),1))"),"") | G15: {=IF(C15=1,XLOOKUP(C15,Cotizador!D:D,Cotizador!E:E,"",0,1),"")} | J15: =IF(I15="","",SUMIF(Cotizador!I$1:V$1,I15,Cotizador!I$2:V$2)) | L15: {=IF(COUNTIF(L$1:L14,A$2)=SUMIF(A:A,A$2,D:D),IF(COUNTIF(L$1:L14,XLOOKUP(A$2,Implementos!B:B,Implementos!C:C,"",0,1))=SUMIF(A:A,XLOOKUP(A$2,Implementos!B:B,Implementos!C:C,"",0,1),D:D),"",XLOOKUP(A$2,Implementos!B:B,Implementos!C:C,"",0,1)),A$2)} -> Acoplados Rurales | M15: =IF(L15="","",max(M$1:M14)+1) -> 14 | N15: =IF(L15="","",IF(N14="Orden",1,IF(COUNTIFS(N$1:N14,N14,L$1:L14,L15)=SUMIFS(D:D,B:B,N14,A:A,L15),IF(N14=maxifs(B:B,A:A,L15),"",maxifs(N$1:N14,L$1:L14,L15)+1),N14))) -> 1 | O15: =IF(N15="","",SUMIFS(C:C,B:B,N15,A:A,L15)) -> 1 | P15: =IF(N15="","",COUNTIFS(N$1:N15,N15,L$1:L15,L15)) -> 14 | Q15: =IF(U15="","",SUMIF(Productos!E:E,U15,Productos!A:A)) -> 93 | R15: {=IF(L15="","", max(1,SUMIF(I:I,XLOOKUP(U15,Productos!E:E,Productos!G:G,"",0,1),J:J)))} -> 1 | S15: =IF(Q15="","",IF(SUMIFS(Compat_Vetado!D:D,Compat_Vetado!B:B,SUM(G:G),Compat_Vetado!C:C,Q15)=1,"SI",IF(OR(SUMIF(Cotizador!E:E,Q15,Cotizador!G:G)>0,SUMIFS(Compat_Vetado!D:D,Compat_Vetado!B:B,SUM(G:G),Compat_Vetado!C:C,Q15)=-1),"NO",""))) | T15: =IF(Q15="","",IF(S15="SI","x",IF(S15="NO","",IF(AND(OR(V15="",AND(W15<=SUMIF(I:I,V15,J:J),SUMIF(I:I,V15,J:J)<=X15)),OR(Y15="",AND(Z15<=SUMIF(I:I,Y15,J:J),SUMIF(I:I,Y15,J:J)<=AA15)),OR(AB15="",AND(AC15<=SUMIF(I:I,AB15,J:J),SUMIF(I:I,AB15,J:J)<=AD15))),"x","")))) -> x | U15: =IFERROR(__xludf.DUMMYFUNCTION("IF(P15="""","""",IFERROR(INDEX(filter(Productos!E:E,Productos!F:F=L15,Productos!H:H=N15),P15),IF(M15=SUM(D:D),""Finalizar"",""-"")))"),"Medio Tanque Plastico Superior 700 Lts") -> Medio Tanque Plastico Superior 700 Lts | V15: =IFERROR(__xludf.DUMMYFUNCTION("IF(OR($U15="""",COUNTIF($I:$I,IFERROR(unique(filter(Prod_Prop!$H:$H,Prod_Prop!$G:$G=$U15,Prod_Prop!$E:$E=V$1)),""Check""))=0),"""",IFERROR(unique(filter(Prod_Prop!$H:$H,Prod_Prop!$G:$G=$U15,Prod_Prop!$E:$E=V$1)),""""))"),"") | W15: =IF(V15="","",SUMIFS(Prod_Prop!$J:$J,Prod_Prop!$B:$B,$Q15,Prod_Prop!$H:$H,V15,Prod_Prop!$I:$I,W$1)*IF(V15="Peso",$R15,1)) | X15: =IF(V15="","",SUMIFS(Prod_Prop!$J:$J,Prod_Prop!$B:$B,$Q15,Prod_Prop!$H:$H,V15,Prod_Prop!$I:$I,X$1)*IF(V15="Peso",$R15,1)) | Y15: =IFERROR(__xludf.DUMMYFUNCTION("IF(OR($U15="""",COUNTIF($I:$I,IFERROR(unique(filter(Prod_Prop!$H:$H,Prod_Prop!$G:$G=$U15,Prod_Prop!$E:$E=Y$1)),""Check""))=0),"""",IFERROR(unique(filter(Prod_Prop!$H:$H,Prod_Prop!$G:$G=$U15,Prod_Prop!$E:$E=Y$1)),""""))"),"") | Z15: =IF(Y15="","",SUMIFS(Prod_Prop!$J:$J,Prod_Prop!$B:$B,$Q15,Prod_Prop!$H:$H,Y15,Prod_Prop!$I:$I,Z$1)*IF(Y15="Peso",$R15,1)) | AA15: =IF(Y15="","",SUMIFS(Prod_Prop!$J:$J,Prod_Prop!$B:$B,$Q15,Prod_Prop!$H:$H,Y15,Prod_Prop!$I:$I,AA$1)*IF(Y15="Peso",$R15,1)) | AB15: =IFERROR(__xludf.DUMMYFUNCTION("IF(OR($U15="""",COUNTIF($I:$I,IFERROR(unique(filter(Prod_Prop!$H:$H,Prod_Prop!$G:$G=$U15,Prod_Prop!$E:$E=AB$1)),""Check""))=0),"""",IFERROR(unique(filter(Prod_Prop!$H:$H,Prod_Prop!$G:$G=$U15,Prod_Prop!$E:$E=AB$1)),""""))"),"") | AC15: =IF(AB15="","",SUMIFS(Prod_Prop!$J:$J,Prod_Prop!$B:$B,$Q15,Prod_Prop!$H:$H,AB15,Prod_Prop!$I:$I,AC$1)*IF(AB15="Peso",$R15,1)) | AD15: =IF(AB15="","",SUMIFS(Prod_Prop!$J:$J,Prod_Prop!$B:$B,$Q15,Prod_Prop!$H:$H,AB15,Prod_Prop!$I:$I,AD$1)*IF(AB15="Peso",$R15,1))
